{
 "cells": [
  {
   "cell_type": "code",
   "execution_count": 1,
   "id": "0ae571b7-43af-4452-85e0-0de080b4bab7",
   "metadata": {},
   "outputs": [
    {
     "name": "stdout",
     "output_type": "stream",
     "text": [
      "Collecting instaloader\n",
      "  Downloading instaloader-4.13.1.tar.gz (65 kB)\n",
      "\u001b[2K     \u001b[90m━━━━━━━━━━━━━━━━━━━━━━━━━━━━━━━━━━━━━━━\u001b[0m \u001b[32m65.1/65.1 kB\u001b[0m \u001b[31m679.1 kB/s\u001b[0m eta \u001b[36m0:00:00\u001b[0ma \u001b[36m0:00:01\u001b[0m\n",
      "\u001b[?25h  Preparing metadata (setup.py) ... \u001b[?25ldone\n",
      "\u001b[?25hCollecting python-telegram-bot\n",
      "  Downloading python_telegram_bot-21.5-py3-none-any.whl.metadata (17 kB)\n",
      "Requirement already satisfied: openpyxl in /Users/iliastulov/miniconda3/lib/python3.12/site-packages (3.1.2)\n",
      "Requirement already satisfied: requests>=2.4 in /Users/iliastulov/miniconda3/lib/python3.12/site-packages (from instaloader) (2.31.0)\n",
      "Requirement already satisfied: httpx~=0.27 in /Users/iliastulov/miniconda3/lib/python3.12/site-packages (from python-telegram-bot) (0.27.0)\n",
      "Requirement already satisfied: et-xmlfile in /Users/iliastulov/miniconda3/lib/python3.12/site-packages (from openpyxl) (1.1.0)\n",
      "Requirement already satisfied: anyio in /Users/iliastulov/miniconda3/lib/python3.12/site-packages (from httpx~=0.27->python-telegram-bot) (4.3.0)\n",
      "Requirement already satisfied: certifi in /Users/iliastulov/miniconda3/lib/python3.12/site-packages (from httpx~=0.27->python-telegram-bot) (2023.11.17)\n",
      "Requirement already satisfied: httpcore==1.* in /Users/iliastulov/miniconda3/lib/python3.12/site-packages (from httpx~=0.27->python-telegram-bot) (1.0.5)\n",
      "Requirement already satisfied: idna in /Users/iliastulov/miniconda3/lib/python3.12/site-packages (from httpx~=0.27->python-telegram-bot) (3.4)\n",
      "Requirement already satisfied: sniffio in /Users/iliastulov/miniconda3/lib/python3.12/site-packages (from httpx~=0.27->python-telegram-bot) (1.3.1)\n",
      "Requirement already satisfied: h11<0.15,>=0.13 in /Users/iliastulov/miniconda3/lib/python3.12/site-packages (from httpcore==1.*->httpx~=0.27->python-telegram-bot) (0.14.0)\n",
      "Requirement already satisfied: charset-normalizer<4,>=2 in /Users/iliastulov/miniconda3/lib/python3.12/site-packages (from requests>=2.4->instaloader) (2.0.4)\n",
      "Requirement already satisfied: urllib3<3,>=1.21.1 in /Users/iliastulov/miniconda3/lib/python3.12/site-packages (from requests>=2.4->instaloader) (2.1.0)\n",
      "Downloading python_telegram_bot-21.5-py3-none-any.whl (648 kB)\n",
      "\u001b[2K   \u001b[90m━━━━━━━━━━━━━━━━━━━━━━━━━━━━━━━━━━━━━━━━\u001b[0m \u001b[32m648.8/648.8 kB\u001b[0m \u001b[31m4.1 MB/s\u001b[0m eta \u001b[36m0:00:00\u001b[0m00:01\u001b[0m00:01\u001b[0m\n",
      "\u001b[?25hBuilding wheels for collected packages: instaloader\n",
      "  Building wheel for instaloader (setup.py) ... \u001b[?25ldone\n",
      "\u001b[?25h  Created wheel for instaloader: filename=instaloader-4.13.1-py3-none-any.whl size=67213 sha256=0c36edc29efb477faecc93a07a9ff434d1e0ec8a9aa75898680e1ea0e68117d5\n",
      "  Stored in directory: /Users/iliastulov/Library/Caches/pip/wheels/56/d6/11/917417bffaacefdf01dfb80498991dd82ae37bb2e0b81a0469\n",
      "Successfully built instaloader\n",
      "Installing collected packages: instaloader, python-telegram-bot\n",
      "Successfully installed instaloader-4.13.1 python-telegram-bot-21.5\n",
      "Note: you may need to restart the kernel to use updated packages.\n"
     ]
    }
   ],
   "source": [
    "pip install instaloader python-telegram-bot openpyxl"
   ]
  },
  {
   "cell_type": "code",
   "execution_count": 3,
   "id": "21225e46-6fe2-4756-ac0d-07d9ded514e7",
   "metadata": {},
   "outputs": [
    {
     "name": "stdout",
     "output_type": "stream",
     "text": [
      "Requirement already satisfied: nest_asyncio in /Users/iliastulov/miniconda3/lib/python3.12/site-packages (1.6.0)\n",
      "\n",
      "\u001b[1m[\u001b[0m\u001b[34;49mnotice\u001b[0m\u001b[1;39;49m]\u001b[0m\u001b[39;49m A new release of pip is available: \u001b[0m\u001b[31;49m24.1.2\u001b[0m\u001b[39;49m -> \u001b[0m\u001b[32;49m24.2\u001b[0m\n",
      "\u001b[1m[\u001b[0m\u001b[34;49mnotice\u001b[0m\u001b[1;39;49m]\u001b[0m\u001b[39;49m To update, run: \u001b[0m\u001b[32;49mpip install --upgrade pip\u001b[0m\n",
      "Note: you may need to restart the kernel to use updated packages.\n"
     ]
    }
   ],
   "source": [
    "pip install nest_asyncio\n"
   ]
  },
  {
   "cell_type": "code",
   "execution_count": 7,
   "id": "d233969e-58fb-42bb-b96a-78ecd2f24c57",
   "metadata": {},
   "outputs": [
    {
     "name": "stderr",
     "output_type": "stream",
     "text": [
      "No error handlers are registered, logging exception.\n",
      "Traceback (most recent call last):\n",
      "  File \"/Users/iliastulov/miniconda3/lib/python3.12/site-packages/telegram/ext/_updater.py\", line 753, in _network_loop_retry\n",
      "    if not await do_action():\n",
      "           ^^^^^^^^^^^^^^^^^\n",
      "  File \"/Users/iliastulov/miniconda3/lib/python3.12/site-packages/telegram/ext/_updater.py\", line 747, in do_action\n",
      "    return action_cb_task.result()\n",
      "           ^^^^^^^^^^^^^^^^^^^^^^^\n",
      "  File \"/Users/iliastulov/miniconda3/lib/python3.12/asyncio/futures.py\", line 203, in result\n",
      "    raise self._exception.with_traceback(self._exception_tb)\n",
      "  File \"/Users/iliastulov/miniconda3/lib/python3.12/asyncio/tasks.py\", line 314, in __step_run_and_handle_result\n",
      "    result = coro.send(None)\n",
      "             ^^^^^^^^^^^^^^^\n",
      "  File \"/Users/iliastulov/miniconda3/lib/python3.12/site-packages/telegram/ext/_updater.py\", line 377, in polling_action_cb\n",
      "    updates = await self.bot.get_updates(\n",
      "              ^^^^^^^^^^^^^^^^^^^^^^^^^^^\n",
      "  File \"/Users/iliastulov/miniconda3/lib/python3.12/site-packages/telegram/ext/_extbot.py\", line 649, in get_updates\n",
      "    updates = await super().get_updates(\n",
      "              ^^^^^^^^^^^^^^^^^^^^^^^^^^\n",
      "  File \"/Users/iliastulov/miniconda3/lib/python3.12/site-packages/telegram/_bot.py\", line 4366, in get_updates\n",
      "    await self._post(\n",
      "  File \"/Users/iliastulov/miniconda3/lib/python3.12/site-packages/telegram/_bot.py\", line 623, in _post\n",
      "    return await self._do_post(\n",
      "           ^^^^^^^^^^^^^^^^^^^^\n",
      "  File \"/Users/iliastulov/miniconda3/lib/python3.12/site-packages/telegram/ext/_extbot.py\", line 355, in _do_post\n",
      "    return await super()._do_post(\n",
      "           ^^^^^^^^^^^^^^^^^^^^^^^\n",
      "  File \"/Users/iliastulov/miniconda3/lib/python3.12/site-packages/telegram/_bot.py\", line 652, in _do_post\n",
      "    result = await request.post(\n",
      "             ^^^^^^^^^^^^^^^^^^^\n",
      "  File \"/Users/iliastulov/miniconda3/lib/python3.12/site-packages/telegram/request/_baserequest.py\", line 201, in post\n",
      "    result = await self._request_wrapper(\n",
      "             ^^^^^^^^^^^^^^^^^^^^^^^^^^^^\n",
      "  File \"/Users/iliastulov/miniconda3/lib/python3.12/site-packages/telegram/request/_baserequest.py\", line 384, in _request_wrapper\n",
      "    raise Conflict(message)\n",
      "telegram.error.Conflict: Conflict: terminated by other getUpdates request; make sure that only one bot instance is running\n",
      "No error handlers are registered, logging exception.\n",
      "Traceback (most recent call last):\n",
      "  File \"/Users/iliastulov/miniconda3/lib/python3.12/site-packages/telegram/ext/_updater.py\", line 753, in _network_loop_retry\n",
      "    if not await do_action():\n",
      "           ^^^^^^^^^^^^^^^^^\n",
      "  File \"/Users/iliastulov/miniconda3/lib/python3.12/site-packages/telegram/ext/_updater.py\", line 747, in do_action\n",
      "    return action_cb_task.result()\n",
      "           ^^^^^^^^^^^^^^^^^^^^^^^\n",
      "  File \"/Users/iliastulov/miniconda3/lib/python3.12/asyncio/futures.py\", line 203, in result\n",
      "    raise self._exception.with_traceback(self._exception_tb)\n",
      "  File \"/Users/iliastulov/miniconda3/lib/python3.12/asyncio/tasks.py\", line 314, in __step_run_and_handle_result\n",
      "    result = coro.send(None)\n",
      "             ^^^^^^^^^^^^^^^\n",
      "  File \"/Users/iliastulov/miniconda3/lib/python3.12/site-packages/telegram/ext/_updater.py\", line 377, in polling_action_cb\n",
      "    updates = await self.bot.get_updates(\n",
      "              ^^^^^^^^^^^^^^^^^^^^^^^^^^^\n",
      "  File \"/Users/iliastulov/miniconda3/lib/python3.12/site-packages/telegram/ext/_extbot.py\", line 649, in get_updates\n",
      "    updates = await super().get_updates(\n",
      "              ^^^^^^^^^^^^^^^^^^^^^^^^^^\n",
      "  File \"/Users/iliastulov/miniconda3/lib/python3.12/site-packages/telegram/_bot.py\", line 4366, in get_updates\n",
      "    await self._post(\n",
      "  File \"/Users/iliastulov/miniconda3/lib/python3.12/site-packages/telegram/_bot.py\", line 623, in _post\n",
      "    return await self._do_post(\n",
      "           ^^^^^^^^^^^^^^^^^^^^\n",
      "  File \"/Users/iliastulov/miniconda3/lib/python3.12/site-packages/telegram/ext/_extbot.py\", line 355, in _do_post\n",
      "    return await super()._do_post(\n",
      "           ^^^^^^^^^^^^^^^^^^^^^^^\n",
      "  File \"/Users/iliastulov/miniconda3/lib/python3.12/site-packages/telegram/_bot.py\", line 652, in _do_post\n",
      "    result = await request.post(\n",
      "             ^^^^^^^^^^^^^^^^^^^\n",
      "  File \"/Users/iliastulov/miniconda3/lib/python3.12/site-packages/telegram/request/_baserequest.py\", line 201, in post\n",
      "    result = await self._request_wrapper(\n",
      "             ^^^^^^^^^^^^^^^^^^^^^^^^^^^^\n",
      "  File \"/Users/iliastulov/miniconda3/lib/python3.12/site-packages/telegram/request/_baserequest.py\", line 384, in _request_wrapper\n",
      "    raise Conflict(message)\n",
      "telegram.error.Conflict: Conflict: terminated by other getUpdates request; make sure that only one bot instance is running\n",
      "No error handlers are registered, logging exception.\n",
      "Traceback (most recent call last):\n",
      "  File \"/Users/iliastulov/miniconda3/lib/python3.12/site-packages/telegram/ext/_updater.py\", line 753, in _network_loop_retry\n",
      "    if not await do_action():\n",
      "           ^^^^^^^^^^^^^^^^^\n",
      "  File \"/Users/iliastulov/miniconda3/lib/python3.12/site-packages/telegram/ext/_updater.py\", line 747, in do_action\n",
      "    return action_cb_task.result()\n",
      "           ^^^^^^^^^^^^^^^^^^^^^^^\n",
      "  File \"/Users/iliastulov/miniconda3/lib/python3.12/asyncio/futures.py\", line 203, in result\n",
      "    raise self._exception.with_traceback(self._exception_tb)\n",
      "  File \"/Users/iliastulov/miniconda3/lib/python3.12/asyncio/tasks.py\", line 314, in __step_run_and_handle_result\n",
      "    result = coro.send(None)\n",
      "             ^^^^^^^^^^^^^^^\n",
      "  File \"/Users/iliastulov/miniconda3/lib/python3.12/site-packages/telegram/ext/_updater.py\", line 377, in polling_action_cb\n",
      "    updates = await self.bot.get_updates(\n",
      "              ^^^^^^^^^^^^^^^^^^^^^^^^^^^\n",
      "  File \"/Users/iliastulov/miniconda3/lib/python3.12/site-packages/telegram/ext/_extbot.py\", line 649, in get_updates\n",
      "    updates = await super().get_updates(\n",
      "              ^^^^^^^^^^^^^^^^^^^^^^^^^^\n",
      "  File \"/Users/iliastulov/miniconda3/lib/python3.12/site-packages/telegram/_bot.py\", line 4366, in get_updates\n",
      "    await self._post(\n",
      "  File \"/Users/iliastulov/miniconda3/lib/python3.12/site-packages/telegram/_bot.py\", line 623, in _post\n",
      "    return await self._do_post(\n",
      "           ^^^^^^^^^^^^^^^^^^^^\n",
      "  File \"/Users/iliastulov/miniconda3/lib/python3.12/site-packages/telegram/ext/_extbot.py\", line 355, in _do_post\n",
      "    return await super()._do_post(\n",
      "           ^^^^^^^^^^^^^^^^^^^^^^^\n",
      "  File \"/Users/iliastulov/miniconda3/lib/python3.12/site-packages/telegram/_bot.py\", line 652, in _do_post\n",
      "    result = await request.post(\n",
      "             ^^^^^^^^^^^^^^^^^^^\n",
      "  File \"/Users/iliastulov/miniconda3/lib/python3.12/site-packages/telegram/request/_baserequest.py\", line 201, in post\n",
      "    result = await self._request_wrapper(\n",
      "             ^^^^^^^^^^^^^^^^^^^^^^^^^^^^\n",
      "  File \"/Users/iliastulov/miniconda3/lib/python3.12/site-packages/telegram/request/_baserequest.py\", line 384, in _request_wrapper\n",
      "    raise Conflict(message)\n",
      "telegram.error.Conflict: Conflict: terminated by other getUpdates request; make sure that only one bot instance is running\n",
      "No error handlers are registered, logging exception.\n",
      "Traceback (most recent call last):\n",
      "  File \"/Users/iliastulov/miniconda3/lib/python3.12/site-packages/telegram/ext/_updater.py\", line 753, in _network_loop_retry\n",
      "    if not await do_action():\n",
      "           ^^^^^^^^^^^^^^^^^\n",
      "  File \"/Users/iliastulov/miniconda3/lib/python3.12/site-packages/telegram/ext/_updater.py\", line 747, in do_action\n",
      "    return action_cb_task.result()\n",
      "           ^^^^^^^^^^^^^^^^^^^^^^^\n",
      "  File \"/Users/iliastulov/miniconda3/lib/python3.12/asyncio/futures.py\", line 203, in result\n",
      "    raise self._exception.with_traceback(self._exception_tb)\n",
      "  File \"/Users/iliastulov/miniconda3/lib/python3.12/asyncio/tasks.py\", line 314, in __step_run_and_handle_result\n",
      "    result = coro.send(None)\n",
      "             ^^^^^^^^^^^^^^^\n",
      "  File \"/Users/iliastulov/miniconda3/lib/python3.12/site-packages/telegram/ext/_updater.py\", line 377, in polling_action_cb\n",
      "    updates = await self.bot.get_updates(\n",
      "              ^^^^^^^^^^^^^^^^^^^^^^^^^^^\n",
      "  File \"/Users/iliastulov/miniconda3/lib/python3.12/site-packages/telegram/ext/_extbot.py\", line 649, in get_updates\n",
      "    updates = await super().get_updates(\n",
      "              ^^^^^^^^^^^^^^^^^^^^^^^^^^\n",
      "  File \"/Users/iliastulov/miniconda3/lib/python3.12/site-packages/telegram/_bot.py\", line 4366, in get_updates\n",
      "    await self._post(\n",
      "  File \"/Users/iliastulov/miniconda3/lib/python3.12/site-packages/telegram/_bot.py\", line 623, in _post\n",
      "    return await self._do_post(\n",
      "           ^^^^^^^^^^^^^^^^^^^^\n",
      "  File \"/Users/iliastulov/miniconda3/lib/python3.12/site-packages/telegram/ext/_extbot.py\", line 355, in _do_post\n",
      "    return await super()._do_post(\n",
      "           ^^^^^^^^^^^^^^^^^^^^^^^\n",
      "  File \"/Users/iliastulov/miniconda3/lib/python3.12/site-packages/telegram/_bot.py\", line 652, in _do_post\n",
      "    result = await request.post(\n",
      "             ^^^^^^^^^^^^^^^^^^^\n",
      "  File \"/Users/iliastulov/miniconda3/lib/python3.12/site-packages/telegram/request/_baserequest.py\", line 201, in post\n",
      "    result = await self._request_wrapper(\n",
      "             ^^^^^^^^^^^^^^^^^^^^^^^^^^^^\n",
      "  File \"/Users/iliastulov/miniconda3/lib/python3.12/site-packages/telegram/request/_baserequest.py\", line 384, in _request_wrapper\n",
      "    raise Conflict(message)\n",
      "telegram.error.Conflict: Conflict: terminated by other getUpdates request; make sure that only one bot instance is running\n",
      "No error handlers are registered, logging exception.\n",
      "Traceback (most recent call last):\n",
      "  File \"/Users/iliastulov/miniconda3/lib/python3.12/site-packages/telegram/ext/_updater.py\", line 753, in _network_loop_retry\n",
      "    if not await do_action():\n",
      "           ^^^^^^^^^^^^^^^^^\n",
      "  File \"/Users/iliastulov/miniconda3/lib/python3.12/site-packages/telegram/ext/_updater.py\", line 747, in do_action\n",
      "    return action_cb_task.result()\n",
      "           ^^^^^^^^^^^^^^^^^^^^^^^\n",
      "  File \"/Users/iliastulov/miniconda3/lib/python3.12/asyncio/futures.py\", line 203, in result\n",
      "    raise self._exception.with_traceback(self._exception_tb)\n",
      "  File \"/Users/iliastulov/miniconda3/lib/python3.12/asyncio/tasks.py\", line 314, in __step_run_and_handle_result\n",
      "    result = coro.send(None)\n",
      "             ^^^^^^^^^^^^^^^\n",
      "  File \"/Users/iliastulov/miniconda3/lib/python3.12/site-packages/telegram/ext/_updater.py\", line 377, in polling_action_cb\n",
      "    updates = await self.bot.get_updates(\n",
      "              ^^^^^^^^^^^^^^^^^^^^^^^^^^^\n",
      "  File \"/Users/iliastulov/miniconda3/lib/python3.12/site-packages/telegram/ext/_extbot.py\", line 649, in get_updates\n",
      "    updates = await super().get_updates(\n",
      "              ^^^^^^^^^^^^^^^^^^^^^^^^^^\n",
      "  File \"/Users/iliastulov/miniconda3/lib/python3.12/site-packages/telegram/_bot.py\", line 4366, in get_updates\n",
      "    await self._post(\n",
      "  File \"/Users/iliastulov/miniconda3/lib/python3.12/site-packages/telegram/_bot.py\", line 623, in _post\n",
      "    return await self._do_post(\n",
      "           ^^^^^^^^^^^^^^^^^^^^\n",
      "  File \"/Users/iliastulov/miniconda3/lib/python3.12/site-packages/telegram/ext/_extbot.py\", line 355, in _do_post\n",
      "    return await super()._do_post(\n",
      "           ^^^^^^^^^^^^^^^^^^^^^^^\n",
      "  File \"/Users/iliastulov/miniconda3/lib/python3.12/site-packages/telegram/_bot.py\", line 652, in _do_post\n",
      "    result = await request.post(\n",
      "             ^^^^^^^^^^^^^^^^^^^\n",
      "  File \"/Users/iliastulov/miniconda3/lib/python3.12/site-packages/telegram/request/_baserequest.py\", line 201, in post\n",
      "    result = await self._request_wrapper(\n",
      "             ^^^^^^^^^^^^^^^^^^^^^^^^^^^^\n",
      "  File \"/Users/iliastulov/miniconda3/lib/python3.12/site-packages/telegram/request/_baserequest.py\", line 384, in _request_wrapper\n",
      "    raise Conflict(message)\n",
      "telegram.error.Conflict: Conflict: terminated by other getUpdates request; make sure that only one bot instance is running\n",
      "No error handlers are registered, logging exception.\n",
      "Traceback (most recent call last):\n",
      "  File \"/Users/iliastulov/miniconda3/lib/python3.12/site-packages/telegram/ext/_updater.py\", line 753, in _network_loop_retry\n",
      "    if not await do_action():\n",
      "           ^^^^^^^^^^^^^^^^^\n",
      "  File \"/Users/iliastulov/miniconda3/lib/python3.12/site-packages/telegram/ext/_updater.py\", line 747, in do_action\n",
      "    return action_cb_task.result()\n",
      "           ^^^^^^^^^^^^^^^^^^^^^^^\n",
      "  File \"/Users/iliastulov/miniconda3/lib/python3.12/asyncio/futures.py\", line 203, in result\n",
      "    raise self._exception.with_traceback(self._exception_tb)\n",
      "  File \"/Users/iliastulov/miniconda3/lib/python3.12/asyncio/tasks.py\", line 314, in __step_run_and_handle_result\n",
      "    result = coro.send(None)\n",
      "             ^^^^^^^^^^^^^^^\n",
      "  File \"/Users/iliastulov/miniconda3/lib/python3.12/site-packages/telegram/ext/_updater.py\", line 377, in polling_action_cb\n",
      "    updates = await self.bot.get_updates(\n",
      "              ^^^^^^^^^^^^^^^^^^^^^^^^^^^\n",
      "  File \"/Users/iliastulov/miniconda3/lib/python3.12/site-packages/telegram/ext/_extbot.py\", line 649, in get_updates\n",
      "    updates = await super().get_updates(\n",
      "              ^^^^^^^^^^^^^^^^^^^^^^^^^^\n",
      "  File \"/Users/iliastulov/miniconda3/lib/python3.12/site-packages/telegram/_bot.py\", line 4366, in get_updates\n",
      "    await self._post(\n",
      "  File \"/Users/iliastulov/miniconda3/lib/python3.12/site-packages/telegram/_bot.py\", line 623, in _post\n",
      "    return await self._do_post(\n",
      "           ^^^^^^^^^^^^^^^^^^^^\n",
      "  File \"/Users/iliastulov/miniconda3/lib/python3.12/site-packages/telegram/ext/_extbot.py\", line 355, in _do_post\n",
      "    return await super()._do_post(\n",
      "           ^^^^^^^^^^^^^^^^^^^^^^^\n",
      "  File \"/Users/iliastulov/miniconda3/lib/python3.12/site-packages/telegram/_bot.py\", line 652, in _do_post\n",
      "    result = await request.post(\n",
      "             ^^^^^^^^^^^^^^^^^^^\n",
      "  File \"/Users/iliastulov/miniconda3/lib/python3.12/site-packages/telegram/request/_baserequest.py\", line 201, in post\n",
      "    result = await self._request_wrapper(\n",
      "             ^^^^^^^^^^^^^^^^^^^^^^^^^^^^\n",
      "  File \"/Users/iliastulov/miniconda3/lib/python3.12/site-packages/telegram/request/_baserequest.py\", line 384, in _request_wrapper\n",
      "    raise Conflict(message)\n",
      "telegram.error.Conflict: Conflict: terminated by other getUpdates request; make sure that only one bot instance is running\n",
      "No error handlers are registered, logging exception.\n",
      "Traceback (most recent call last):\n",
      "  File \"/Users/iliastulov/miniconda3/lib/python3.12/site-packages/telegram/ext/_updater.py\", line 753, in _network_loop_retry\n",
      "    if not await do_action():\n",
      "           ^^^^^^^^^^^^^^^^^\n",
      "  File \"/Users/iliastulov/miniconda3/lib/python3.12/site-packages/telegram/ext/_updater.py\", line 747, in do_action\n",
      "    return action_cb_task.result()\n",
      "           ^^^^^^^^^^^^^^^^^^^^^^^\n",
      "  File \"/Users/iliastulov/miniconda3/lib/python3.12/asyncio/futures.py\", line 203, in result\n",
      "    raise self._exception.with_traceback(self._exception_tb)\n",
      "  File \"/Users/iliastulov/miniconda3/lib/python3.12/asyncio/tasks.py\", line 314, in __step_run_and_handle_result\n",
      "    result = coro.send(None)\n",
      "             ^^^^^^^^^^^^^^^\n",
      "  File \"/Users/iliastulov/miniconda3/lib/python3.12/site-packages/telegram/ext/_updater.py\", line 377, in polling_action_cb\n",
      "    updates = await self.bot.get_updates(\n",
      "              ^^^^^^^^^^^^^^^^^^^^^^^^^^^\n",
      "  File \"/Users/iliastulov/miniconda3/lib/python3.12/site-packages/telegram/ext/_extbot.py\", line 649, in get_updates\n",
      "    updates = await super().get_updates(\n",
      "              ^^^^^^^^^^^^^^^^^^^^^^^^^^\n",
      "  File \"/Users/iliastulov/miniconda3/lib/python3.12/site-packages/telegram/_bot.py\", line 4366, in get_updates\n",
      "    await self._post(\n",
      "  File \"/Users/iliastulov/miniconda3/lib/python3.12/site-packages/telegram/_bot.py\", line 623, in _post\n",
      "    return await self._do_post(\n",
      "           ^^^^^^^^^^^^^^^^^^^^\n",
      "  File \"/Users/iliastulov/miniconda3/lib/python3.12/site-packages/telegram/ext/_extbot.py\", line 355, in _do_post\n",
      "    return await super()._do_post(\n",
      "           ^^^^^^^^^^^^^^^^^^^^^^^\n",
      "  File \"/Users/iliastulov/miniconda3/lib/python3.12/site-packages/telegram/_bot.py\", line 652, in _do_post\n",
      "    result = await request.post(\n",
      "             ^^^^^^^^^^^^^^^^^^^\n",
      "  File \"/Users/iliastulov/miniconda3/lib/python3.12/site-packages/telegram/request/_baserequest.py\", line 201, in post\n",
      "    result = await self._request_wrapper(\n",
      "             ^^^^^^^^^^^^^^^^^^^^^^^^^^^^\n",
      "  File \"/Users/iliastulov/miniconda3/lib/python3.12/site-packages/telegram/request/_baserequest.py\", line 384, in _request_wrapper\n",
      "    raise Conflict(message)\n",
      "telegram.error.Conflict: Conflict: terminated by other getUpdates request; make sure that only one bot instance is running\n",
      "No error handlers are registered, logging exception.\n",
      "Traceback (most recent call last):\n",
      "  File \"/Users/iliastulov/miniconda3/lib/python3.12/site-packages/telegram/ext/_updater.py\", line 753, in _network_loop_retry\n",
      "    if not await do_action():\n",
      "           ^^^^^^^^^^^^^^^^^\n",
      "  File \"/Users/iliastulov/miniconda3/lib/python3.12/site-packages/telegram/ext/_updater.py\", line 747, in do_action\n",
      "    return action_cb_task.result()\n",
      "           ^^^^^^^^^^^^^^^^^^^^^^^\n",
      "  File \"/Users/iliastulov/miniconda3/lib/python3.12/asyncio/futures.py\", line 203, in result\n",
      "    raise self._exception.with_traceback(self._exception_tb)\n",
      "  File \"/Users/iliastulov/miniconda3/lib/python3.12/asyncio/tasks.py\", line 314, in __step_run_and_handle_result\n",
      "    result = coro.send(None)\n",
      "             ^^^^^^^^^^^^^^^\n",
      "  File \"/Users/iliastulov/miniconda3/lib/python3.12/site-packages/telegram/ext/_updater.py\", line 377, in polling_action_cb\n",
      "    updates = await self.bot.get_updates(\n",
      "              ^^^^^^^^^^^^^^^^^^^^^^^^^^^\n",
      "  File \"/Users/iliastulov/miniconda3/lib/python3.12/site-packages/telegram/ext/_extbot.py\", line 649, in get_updates\n",
      "    updates = await super().get_updates(\n",
      "              ^^^^^^^^^^^^^^^^^^^^^^^^^^\n",
      "  File \"/Users/iliastulov/miniconda3/lib/python3.12/site-packages/telegram/_bot.py\", line 4366, in get_updates\n",
      "    await self._post(\n",
      "  File \"/Users/iliastulov/miniconda3/lib/python3.12/site-packages/telegram/_bot.py\", line 623, in _post\n",
      "    return await self._do_post(\n",
      "           ^^^^^^^^^^^^^^^^^^^^\n",
      "  File \"/Users/iliastulov/miniconda3/lib/python3.12/site-packages/telegram/ext/_extbot.py\", line 355, in _do_post\n",
      "    return await super()._do_post(\n",
      "           ^^^^^^^^^^^^^^^^^^^^^^^\n",
      "  File \"/Users/iliastulov/miniconda3/lib/python3.12/site-packages/telegram/_bot.py\", line 652, in _do_post\n",
      "    result = await request.post(\n",
      "             ^^^^^^^^^^^^^^^^^^^\n",
      "  File \"/Users/iliastulov/miniconda3/lib/python3.12/site-packages/telegram/request/_baserequest.py\", line 201, in post\n",
      "    result = await self._request_wrapper(\n",
      "             ^^^^^^^^^^^^^^^^^^^^^^^^^^^^\n",
      "  File \"/Users/iliastulov/miniconda3/lib/python3.12/site-packages/telegram/request/_baserequest.py\", line 384, in _request_wrapper\n",
      "    raise Conflict(message)\n",
      "telegram.error.Conflict: Conflict: terminated by other getUpdates request; make sure that only one bot instance is running\n",
      "No error handlers are registered, logging exception.\n",
      "Traceback (most recent call last):\n",
      "  File \"/Users/iliastulov/miniconda3/lib/python3.12/site-packages/telegram/ext/_updater.py\", line 753, in _network_loop_retry\n",
      "    if not await do_action():\n",
      "           ^^^^^^^^^^^^^^^^^\n",
      "  File \"/Users/iliastulov/miniconda3/lib/python3.12/site-packages/telegram/ext/_updater.py\", line 747, in do_action\n",
      "    return action_cb_task.result()\n",
      "           ^^^^^^^^^^^^^^^^^^^^^^^\n",
      "  File \"/Users/iliastulov/miniconda3/lib/python3.12/asyncio/futures.py\", line 203, in result\n",
      "    raise self._exception.with_traceback(self._exception_tb)\n",
      "  File \"/Users/iliastulov/miniconda3/lib/python3.12/asyncio/tasks.py\", line 314, in __step_run_and_handle_result\n",
      "    result = coro.send(None)\n",
      "             ^^^^^^^^^^^^^^^\n",
      "  File \"/Users/iliastulov/miniconda3/lib/python3.12/site-packages/telegram/ext/_updater.py\", line 377, in polling_action_cb\n",
      "    updates = await self.bot.get_updates(\n",
      "              ^^^^^^^^^^^^^^^^^^^^^^^^^^^\n",
      "  File \"/Users/iliastulov/miniconda3/lib/python3.12/site-packages/telegram/ext/_extbot.py\", line 649, in get_updates\n",
      "    updates = await super().get_updates(\n",
      "              ^^^^^^^^^^^^^^^^^^^^^^^^^^\n",
      "  File \"/Users/iliastulov/miniconda3/lib/python3.12/site-packages/telegram/_bot.py\", line 4366, in get_updates\n",
      "    await self._post(\n",
      "  File \"/Users/iliastulov/miniconda3/lib/python3.12/site-packages/telegram/_bot.py\", line 623, in _post\n",
      "    return await self._do_post(\n",
      "           ^^^^^^^^^^^^^^^^^^^^\n",
      "  File \"/Users/iliastulov/miniconda3/lib/python3.12/site-packages/telegram/ext/_extbot.py\", line 355, in _do_post\n",
      "    return await super()._do_post(\n",
      "           ^^^^^^^^^^^^^^^^^^^^^^^\n",
      "  File \"/Users/iliastulov/miniconda3/lib/python3.12/site-packages/telegram/_bot.py\", line 652, in _do_post\n",
      "    result = await request.post(\n",
      "             ^^^^^^^^^^^^^^^^^^^\n",
      "  File \"/Users/iliastulov/miniconda3/lib/python3.12/site-packages/telegram/request/_baserequest.py\", line 201, in post\n",
      "    result = await self._request_wrapper(\n",
      "             ^^^^^^^^^^^^^^^^^^^^^^^^^^^^\n",
      "  File \"/Users/iliastulov/miniconda3/lib/python3.12/site-packages/telegram/request/_baserequest.py\", line 384, in _request_wrapper\n",
      "    raise Conflict(message)\n",
      "telegram.error.Conflict: Conflict: terminated by other getUpdates request; make sure that only one bot instance is running\n",
      "No error handlers are registered, logging exception.\n",
      "Traceback (most recent call last):\n",
      "  File \"/Users/iliastulov/miniconda3/lib/python3.12/site-packages/telegram/ext/_updater.py\", line 753, in _network_loop_retry\n",
      "    if not await do_action():\n",
      "           ^^^^^^^^^^^^^^^^^\n",
      "  File \"/Users/iliastulov/miniconda3/lib/python3.12/site-packages/telegram/ext/_updater.py\", line 747, in do_action\n",
      "    return action_cb_task.result()\n",
      "           ^^^^^^^^^^^^^^^^^^^^^^^\n",
      "  File \"/Users/iliastulov/miniconda3/lib/python3.12/asyncio/futures.py\", line 203, in result\n",
      "    raise self._exception.with_traceback(self._exception_tb)\n",
      "  File \"/Users/iliastulov/miniconda3/lib/python3.12/asyncio/tasks.py\", line 314, in __step_run_and_handle_result\n",
      "    result = coro.send(None)\n",
      "             ^^^^^^^^^^^^^^^\n",
      "  File \"/Users/iliastulov/miniconda3/lib/python3.12/site-packages/telegram/ext/_updater.py\", line 377, in polling_action_cb\n",
      "    updates = await self.bot.get_updates(\n",
      "              ^^^^^^^^^^^^^^^^^^^^^^^^^^^\n",
      "  File \"/Users/iliastulov/miniconda3/lib/python3.12/site-packages/telegram/ext/_extbot.py\", line 649, in get_updates\n",
      "    updates = await super().get_updates(\n",
      "              ^^^^^^^^^^^^^^^^^^^^^^^^^^\n",
      "  File \"/Users/iliastulov/miniconda3/lib/python3.12/site-packages/telegram/_bot.py\", line 4366, in get_updates\n",
      "    await self._post(\n",
      "  File \"/Users/iliastulov/miniconda3/lib/python3.12/site-packages/telegram/_bot.py\", line 623, in _post\n",
      "    return await self._do_post(\n",
      "           ^^^^^^^^^^^^^^^^^^^^\n",
      "  File \"/Users/iliastulov/miniconda3/lib/python3.12/site-packages/telegram/ext/_extbot.py\", line 355, in _do_post\n",
      "    return await super()._do_post(\n",
      "           ^^^^^^^^^^^^^^^^^^^^^^^\n",
      "  File \"/Users/iliastulov/miniconda3/lib/python3.12/site-packages/telegram/_bot.py\", line 652, in _do_post\n",
      "    result = await request.post(\n",
      "             ^^^^^^^^^^^^^^^^^^^\n",
      "  File \"/Users/iliastulov/miniconda3/lib/python3.12/site-packages/telegram/request/_baserequest.py\", line 201, in post\n",
      "    result = await self._request_wrapper(\n",
      "             ^^^^^^^^^^^^^^^^^^^^^^^^^^^^\n",
      "  File \"/Users/iliastulov/miniconda3/lib/python3.12/site-packages/telegram/request/_baserequest.py\", line 384, in _request_wrapper\n",
      "    raise Conflict(message)\n",
      "telegram.error.Conflict: Conflict: terminated by other getUpdates request; make sure that only one bot instance is running\n",
      "No error handlers are registered, logging exception.\n",
      "Traceback (most recent call last):\n",
      "  File \"/Users/iliastulov/miniconda3/lib/python3.12/site-packages/telegram/ext/_updater.py\", line 753, in _network_loop_retry\n",
      "    if not await do_action():\n",
      "           ^^^^^^^^^^^^^^^^^\n",
      "  File \"/Users/iliastulov/miniconda3/lib/python3.12/site-packages/telegram/ext/_updater.py\", line 747, in do_action\n",
      "    return action_cb_task.result()\n",
      "           ^^^^^^^^^^^^^^^^^^^^^^^\n",
      "  File \"/Users/iliastulov/miniconda3/lib/python3.12/asyncio/futures.py\", line 203, in result\n",
      "    raise self._exception.with_traceback(self._exception_tb)\n",
      "  File \"/Users/iliastulov/miniconda3/lib/python3.12/asyncio/tasks.py\", line 314, in __step_run_and_handle_result\n",
      "    result = coro.send(None)\n",
      "             ^^^^^^^^^^^^^^^\n",
      "  File \"/Users/iliastulov/miniconda3/lib/python3.12/site-packages/telegram/ext/_updater.py\", line 377, in polling_action_cb\n",
      "    updates = await self.bot.get_updates(\n",
      "              ^^^^^^^^^^^^^^^^^^^^^^^^^^^\n",
      "  File \"/Users/iliastulov/miniconda3/lib/python3.12/site-packages/telegram/ext/_extbot.py\", line 649, in get_updates\n",
      "    updates = await super().get_updates(\n",
      "              ^^^^^^^^^^^^^^^^^^^^^^^^^^\n",
      "  File \"/Users/iliastulov/miniconda3/lib/python3.12/site-packages/telegram/_bot.py\", line 4366, in get_updates\n",
      "    await self._post(\n",
      "  File \"/Users/iliastulov/miniconda3/lib/python3.12/site-packages/telegram/_bot.py\", line 623, in _post\n",
      "    return await self._do_post(\n",
      "           ^^^^^^^^^^^^^^^^^^^^\n",
      "  File \"/Users/iliastulov/miniconda3/lib/python3.12/site-packages/telegram/ext/_extbot.py\", line 355, in _do_post\n",
      "    return await super()._do_post(\n",
      "           ^^^^^^^^^^^^^^^^^^^^^^^\n",
      "  File \"/Users/iliastulov/miniconda3/lib/python3.12/site-packages/telegram/_bot.py\", line 652, in _do_post\n",
      "    result = await request.post(\n",
      "             ^^^^^^^^^^^^^^^^^^^\n",
      "  File \"/Users/iliastulov/miniconda3/lib/python3.12/site-packages/telegram/request/_baserequest.py\", line 201, in post\n",
      "    result = await self._request_wrapper(\n",
      "             ^^^^^^^^^^^^^^^^^^^^^^^^^^^^\n",
      "  File \"/Users/iliastulov/miniconda3/lib/python3.12/site-packages/telegram/request/_baserequest.py\", line 384, in _request_wrapper\n",
      "    raise Conflict(message)\n",
      "telegram.error.Conflict: Conflict: terminated by other getUpdates request; make sure that only one bot instance is running\n",
      "No error handlers are registered, logging exception.\n",
      "Traceback (most recent call last):\n",
      "  File \"/Users/iliastulov/miniconda3/lib/python3.12/site-packages/telegram/ext/_updater.py\", line 753, in _network_loop_retry\n",
      "    if not await do_action():\n",
      "           ^^^^^^^^^^^^^^^^^\n",
      "  File \"/Users/iliastulov/miniconda3/lib/python3.12/site-packages/telegram/ext/_updater.py\", line 747, in do_action\n",
      "    return action_cb_task.result()\n",
      "           ^^^^^^^^^^^^^^^^^^^^^^^\n",
      "  File \"/Users/iliastulov/miniconda3/lib/python3.12/asyncio/futures.py\", line 203, in result\n",
      "    raise self._exception.with_traceback(self._exception_tb)\n",
      "  File \"/Users/iliastulov/miniconda3/lib/python3.12/asyncio/tasks.py\", line 314, in __step_run_and_handle_result\n",
      "    result = coro.send(None)\n",
      "             ^^^^^^^^^^^^^^^\n",
      "  File \"/Users/iliastulov/miniconda3/lib/python3.12/site-packages/telegram/ext/_updater.py\", line 377, in polling_action_cb\n",
      "    updates = await self.bot.get_updates(\n",
      "              ^^^^^^^^^^^^^^^^^^^^^^^^^^^\n",
      "  File \"/Users/iliastulov/miniconda3/lib/python3.12/site-packages/telegram/ext/_extbot.py\", line 649, in get_updates\n",
      "    updates = await super().get_updates(\n",
      "              ^^^^^^^^^^^^^^^^^^^^^^^^^^\n",
      "  File \"/Users/iliastulov/miniconda3/lib/python3.12/site-packages/telegram/_bot.py\", line 4366, in get_updates\n",
      "    await self._post(\n",
      "  File \"/Users/iliastulov/miniconda3/lib/python3.12/site-packages/telegram/_bot.py\", line 623, in _post\n",
      "    return await self._do_post(\n",
      "           ^^^^^^^^^^^^^^^^^^^^\n",
      "  File \"/Users/iliastulov/miniconda3/lib/python3.12/site-packages/telegram/ext/_extbot.py\", line 355, in _do_post\n",
      "    return await super()._do_post(\n",
      "           ^^^^^^^^^^^^^^^^^^^^^^^\n",
      "  File \"/Users/iliastulov/miniconda3/lib/python3.12/site-packages/telegram/_bot.py\", line 652, in _do_post\n",
      "    result = await request.post(\n",
      "             ^^^^^^^^^^^^^^^^^^^\n",
      "  File \"/Users/iliastulov/miniconda3/lib/python3.12/site-packages/telegram/request/_baserequest.py\", line 201, in post\n",
      "    result = await self._request_wrapper(\n",
      "             ^^^^^^^^^^^^^^^^^^^^^^^^^^^^\n",
      "  File \"/Users/iliastulov/miniconda3/lib/python3.12/site-packages/telegram/request/_baserequest.py\", line 384, in _request_wrapper\n",
      "    raise Conflict(message)\n",
      "telegram.error.Conflict: Conflict: terminated by other getUpdates request; make sure that only one bot instance is running\n",
      "No error handlers are registered, logging exception.\n",
      "Traceback (most recent call last):\n",
      "  File \"/Users/iliastulov/miniconda3/lib/python3.12/site-packages/telegram/ext/_updater.py\", line 753, in _network_loop_retry\n",
      "    if not await do_action():\n",
      "           ^^^^^^^^^^^^^^^^^\n",
      "  File \"/Users/iliastulov/miniconda3/lib/python3.12/site-packages/telegram/ext/_updater.py\", line 747, in do_action\n",
      "    return action_cb_task.result()\n",
      "           ^^^^^^^^^^^^^^^^^^^^^^^\n",
      "  File \"/Users/iliastulov/miniconda3/lib/python3.12/asyncio/futures.py\", line 203, in result\n",
      "    raise self._exception.with_traceback(self._exception_tb)\n",
      "  File \"/Users/iliastulov/miniconda3/lib/python3.12/asyncio/tasks.py\", line 314, in __step_run_and_handle_result\n",
      "    result = coro.send(None)\n",
      "             ^^^^^^^^^^^^^^^\n",
      "  File \"/Users/iliastulov/miniconda3/lib/python3.12/site-packages/telegram/ext/_updater.py\", line 377, in polling_action_cb\n",
      "    updates = await self.bot.get_updates(\n",
      "              ^^^^^^^^^^^^^^^^^^^^^^^^^^^\n",
      "  File \"/Users/iliastulov/miniconda3/lib/python3.12/site-packages/telegram/ext/_extbot.py\", line 649, in get_updates\n",
      "    updates = await super().get_updates(\n",
      "              ^^^^^^^^^^^^^^^^^^^^^^^^^^\n",
      "  File \"/Users/iliastulov/miniconda3/lib/python3.12/site-packages/telegram/_bot.py\", line 4366, in get_updates\n",
      "    await self._post(\n",
      "  File \"/Users/iliastulov/miniconda3/lib/python3.12/site-packages/telegram/_bot.py\", line 623, in _post\n",
      "    return await self._do_post(\n",
      "           ^^^^^^^^^^^^^^^^^^^^\n",
      "  File \"/Users/iliastulov/miniconda3/lib/python3.12/site-packages/telegram/ext/_extbot.py\", line 355, in _do_post\n",
      "    return await super()._do_post(\n",
      "           ^^^^^^^^^^^^^^^^^^^^^^^\n",
      "  File \"/Users/iliastulov/miniconda3/lib/python3.12/site-packages/telegram/_bot.py\", line 652, in _do_post\n",
      "    result = await request.post(\n",
      "             ^^^^^^^^^^^^^^^^^^^\n",
      "  File \"/Users/iliastulov/miniconda3/lib/python3.12/site-packages/telegram/request/_baserequest.py\", line 201, in post\n",
      "    result = await self._request_wrapper(\n",
      "             ^^^^^^^^^^^^^^^^^^^^^^^^^^^^\n",
      "  File \"/Users/iliastulov/miniconda3/lib/python3.12/site-packages/telegram/request/_baserequest.py\", line 384, in _request_wrapper\n",
      "    raise Conflict(message)\n",
      "telegram.error.Conflict: Conflict: terminated by other getUpdates request; make sure that only one bot instance is running\n",
      "No error handlers are registered, logging exception.\n",
      "Traceback (most recent call last):\n",
      "  File \"/Users/iliastulov/miniconda3/lib/python3.12/site-packages/telegram/ext/_updater.py\", line 753, in _network_loop_retry\n",
      "    if not await do_action():\n",
      "           ^^^^^^^^^^^^^^^^^\n",
      "  File \"/Users/iliastulov/miniconda3/lib/python3.12/site-packages/telegram/ext/_updater.py\", line 747, in do_action\n",
      "    return action_cb_task.result()\n",
      "           ^^^^^^^^^^^^^^^^^^^^^^^\n",
      "  File \"/Users/iliastulov/miniconda3/lib/python3.12/asyncio/futures.py\", line 203, in result\n",
      "    raise self._exception.with_traceback(self._exception_tb)\n",
      "  File \"/Users/iliastulov/miniconda3/lib/python3.12/asyncio/tasks.py\", line 314, in __step_run_and_handle_result\n",
      "    result = coro.send(None)\n",
      "             ^^^^^^^^^^^^^^^\n",
      "  File \"/Users/iliastulov/miniconda3/lib/python3.12/site-packages/telegram/ext/_updater.py\", line 377, in polling_action_cb\n",
      "    updates = await self.bot.get_updates(\n",
      "              ^^^^^^^^^^^^^^^^^^^^^^^^^^^\n",
      "  File \"/Users/iliastulov/miniconda3/lib/python3.12/site-packages/telegram/ext/_extbot.py\", line 649, in get_updates\n",
      "    updates = await super().get_updates(\n",
      "              ^^^^^^^^^^^^^^^^^^^^^^^^^^\n",
      "  File \"/Users/iliastulov/miniconda3/lib/python3.12/site-packages/telegram/_bot.py\", line 4366, in get_updates\n",
      "    await self._post(\n",
      "  File \"/Users/iliastulov/miniconda3/lib/python3.12/site-packages/telegram/_bot.py\", line 623, in _post\n",
      "    return await self._do_post(\n",
      "           ^^^^^^^^^^^^^^^^^^^^\n",
      "  File \"/Users/iliastulov/miniconda3/lib/python3.12/site-packages/telegram/ext/_extbot.py\", line 355, in _do_post\n",
      "    return await super()._do_post(\n",
      "           ^^^^^^^^^^^^^^^^^^^^^^^\n",
      "  File \"/Users/iliastulov/miniconda3/lib/python3.12/site-packages/telegram/_bot.py\", line 652, in _do_post\n",
      "    result = await request.post(\n",
      "             ^^^^^^^^^^^^^^^^^^^\n",
      "  File \"/Users/iliastulov/miniconda3/lib/python3.12/site-packages/telegram/request/_baserequest.py\", line 201, in post\n",
      "    result = await self._request_wrapper(\n",
      "             ^^^^^^^^^^^^^^^^^^^^^^^^^^^^\n",
      "  File \"/Users/iliastulov/miniconda3/lib/python3.12/site-packages/telegram/request/_baserequest.py\", line 384, in _request_wrapper\n",
      "    raise Conflict(message)\n",
      "telegram.error.Conflict: Conflict: terminated by other getUpdates request; make sure that only one bot instance is running\n",
      "No error handlers are registered, logging exception.\n",
      "Traceback (most recent call last):\n",
      "  File \"/Users/iliastulov/miniconda3/lib/python3.12/site-packages/telegram/ext/_updater.py\", line 753, in _network_loop_retry\n",
      "    if not await do_action():\n",
      "           ^^^^^^^^^^^^^^^^^\n",
      "  File \"/Users/iliastulov/miniconda3/lib/python3.12/site-packages/telegram/ext/_updater.py\", line 747, in do_action\n",
      "    return action_cb_task.result()\n",
      "           ^^^^^^^^^^^^^^^^^^^^^^^\n",
      "  File \"/Users/iliastulov/miniconda3/lib/python3.12/asyncio/futures.py\", line 203, in result\n",
      "    raise self._exception.with_traceback(self._exception_tb)\n",
      "  File \"/Users/iliastulov/miniconda3/lib/python3.12/asyncio/tasks.py\", line 314, in __step_run_and_handle_result\n",
      "    result = coro.send(None)\n",
      "             ^^^^^^^^^^^^^^^\n",
      "  File \"/Users/iliastulov/miniconda3/lib/python3.12/site-packages/telegram/ext/_updater.py\", line 377, in polling_action_cb\n",
      "    updates = await self.bot.get_updates(\n",
      "              ^^^^^^^^^^^^^^^^^^^^^^^^^^^\n",
      "  File \"/Users/iliastulov/miniconda3/lib/python3.12/site-packages/telegram/ext/_extbot.py\", line 649, in get_updates\n",
      "    updates = await super().get_updates(\n",
      "              ^^^^^^^^^^^^^^^^^^^^^^^^^^\n",
      "  File \"/Users/iliastulov/miniconda3/lib/python3.12/site-packages/telegram/_bot.py\", line 4366, in get_updates\n",
      "    await self._post(\n",
      "  File \"/Users/iliastulov/miniconda3/lib/python3.12/site-packages/telegram/_bot.py\", line 623, in _post\n",
      "    return await self._do_post(\n",
      "           ^^^^^^^^^^^^^^^^^^^^\n",
      "  File \"/Users/iliastulov/miniconda3/lib/python3.12/site-packages/telegram/ext/_extbot.py\", line 355, in _do_post\n",
      "    return await super()._do_post(\n",
      "           ^^^^^^^^^^^^^^^^^^^^^^^\n",
      "  File \"/Users/iliastulov/miniconda3/lib/python3.12/site-packages/telegram/_bot.py\", line 652, in _do_post\n",
      "    result = await request.post(\n",
      "             ^^^^^^^^^^^^^^^^^^^\n",
      "  File \"/Users/iliastulov/miniconda3/lib/python3.12/site-packages/telegram/request/_baserequest.py\", line 201, in post\n",
      "    result = await self._request_wrapper(\n",
      "             ^^^^^^^^^^^^^^^^^^^^^^^^^^^^\n",
      "  File \"/Users/iliastulov/miniconda3/lib/python3.12/site-packages/telegram/request/_baserequest.py\", line 384, in _request_wrapper\n",
      "    raise Conflict(message)\n",
      "telegram.error.Conflict: Conflict: terminated by other getUpdates request; make sure that only one bot instance is running\n",
      "No error handlers are registered, logging exception.\n",
      "Traceback (most recent call last):\n",
      "  File \"/Users/iliastulov/miniconda3/lib/python3.12/site-packages/telegram/ext/_updater.py\", line 753, in _network_loop_retry\n",
      "    if not await do_action():\n",
      "           ^^^^^^^^^^^^^^^^^\n",
      "  File \"/Users/iliastulov/miniconda3/lib/python3.12/site-packages/telegram/ext/_updater.py\", line 747, in do_action\n",
      "    return action_cb_task.result()\n",
      "           ^^^^^^^^^^^^^^^^^^^^^^^\n",
      "  File \"/Users/iliastulov/miniconda3/lib/python3.12/asyncio/futures.py\", line 203, in result\n",
      "    raise self._exception.with_traceback(self._exception_tb)\n",
      "  File \"/Users/iliastulov/miniconda3/lib/python3.12/asyncio/tasks.py\", line 314, in __step_run_and_handle_result\n",
      "    result = coro.send(None)\n",
      "             ^^^^^^^^^^^^^^^\n",
      "  File \"/Users/iliastulov/miniconda3/lib/python3.12/site-packages/telegram/ext/_updater.py\", line 377, in polling_action_cb\n",
      "    updates = await self.bot.get_updates(\n",
      "              ^^^^^^^^^^^^^^^^^^^^^^^^^^^\n",
      "  File \"/Users/iliastulov/miniconda3/lib/python3.12/site-packages/telegram/ext/_extbot.py\", line 649, in get_updates\n",
      "    updates = await super().get_updates(\n",
      "              ^^^^^^^^^^^^^^^^^^^^^^^^^^\n",
      "  File \"/Users/iliastulov/miniconda3/lib/python3.12/site-packages/telegram/_bot.py\", line 4366, in get_updates\n",
      "    await self._post(\n",
      "  File \"/Users/iliastulov/miniconda3/lib/python3.12/site-packages/telegram/_bot.py\", line 623, in _post\n",
      "    return await self._do_post(\n",
      "           ^^^^^^^^^^^^^^^^^^^^\n",
      "  File \"/Users/iliastulov/miniconda3/lib/python3.12/site-packages/telegram/ext/_extbot.py\", line 355, in _do_post\n",
      "    return await super()._do_post(\n",
      "           ^^^^^^^^^^^^^^^^^^^^^^^\n",
      "  File \"/Users/iliastulov/miniconda3/lib/python3.12/site-packages/telegram/_bot.py\", line 652, in _do_post\n",
      "    result = await request.post(\n",
      "             ^^^^^^^^^^^^^^^^^^^\n",
      "  File \"/Users/iliastulov/miniconda3/lib/python3.12/site-packages/telegram/request/_baserequest.py\", line 201, in post\n",
      "    result = await self._request_wrapper(\n",
      "             ^^^^^^^^^^^^^^^^^^^^^^^^^^^^\n",
      "  File \"/Users/iliastulov/miniconda3/lib/python3.12/site-packages/telegram/request/_baserequest.py\", line 384, in _request_wrapper\n",
      "    raise Conflict(message)\n",
      "telegram.error.Conflict: Conflict: terminated by other getUpdates request; make sure that only one bot instance is running\n",
      "No error handlers are registered, logging exception.\n",
      "Traceback (most recent call last):\n",
      "  File \"/Users/iliastulov/miniconda3/lib/python3.12/site-packages/telegram/ext/_updater.py\", line 753, in _network_loop_retry\n",
      "    if not await do_action():\n",
      "           ^^^^^^^^^^^^^^^^^\n",
      "  File \"/Users/iliastulov/miniconda3/lib/python3.12/site-packages/telegram/ext/_updater.py\", line 747, in do_action\n",
      "    return action_cb_task.result()\n",
      "           ^^^^^^^^^^^^^^^^^^^^^^^\n",
      "  File \"/Users/iliastulov/miniconda3/lib/python3.12/asyncio/futures.py\", line 203, in result\n",
      "    raise self._exception.with_traceback(self._exception_tb)\n",
      "  File \"/Users/iliastulov/miniconda3/lib/python3.12/asyncio/tasks.py\", line 314, in __step_run_and_handle_result\n",
      "    result = coro.send(None)\n",
      "             ^^^^^^^^^^^^^^^\n",
      "  File \"/Users/iliastulov/miniconda3/lib/python3.12/site-packages/telegram/ext/_updater.py\", line 377, in polling_action_cb\n",
      "    updates = await self.bot.get_updates(\n",
      "              ^^^^^^^^^^^^^^^^^^^^^^^^^^^\n",
      "  File \"/Users/iliastulov/miniconda3/lib/python3.12/site-packages/telegram/ext/_extbot.py\", line 649, in get_updates\n",
      "    updates = await super().get_updates(\n",
      "              ^^^^^^^^^^^^^^^^^^^^^^^^^^\n",
      "  File \"/Users/iliastulov/miniconda3/lib/python3.12/site-packages/telegram/_bot.py\", line 4366, in get_updates\n",
      "    await self._post(\n",
      "  File \"/Users/iliastulov/miniconda3/lib/python3.12/site-packages/telegram/_bot.py\", line 623, in _post\n",
      "    return await self._do_post(\n",
      "           ^^^^^^^^^^^^^^^^^^^^\n",
      "  File \"/Users/iliastulov/miniconda3/lib/python3.12/site-packages/telegram/ext/_extbot.py\", line 355, in _do_post\n",
      "    return await super()._do_post(\n",
      "           ^^^^^^^^^^^^^^^^^^^^^^^\n",
      "  File \"/Users/iliastulov/miniconda3/lib/python3.12/site-packages/telegram/_bot.py\", line 652, in _do_post\n",
      "    result = await request.post(\n",
      "             ^^^^^^^^^^^^^^^^^^^\n",
      "  File \"/Users/iliastulov/miniconda3/lib/python3.12/site-packages/telegram/request/_baserequest.py\", line 201, in post\n",
      "    result = await self._request_wrapper(\n",
      "             ^^^^^^^^^^^^^^^^^^^^^^^^^^^^\n",
      "  File \"/Users/iliastulov/miniconda3/lib/python3.12/site-packages/telegram/request/_baserequest.py\", line 384, in _request_wrapper\n",
      "    raise Conflict(message)\n",
      "telegram.error.Conflict: Conflict: terminated by other getUpdates request; make sure that only one bot instance is running\n",
      "No error handlers are registered, logging exception.\n",
      "Traceback (most recent call last):\n",
      "  File \"/Users/iliastulov/miniconda3/lib/python3.12/site-packages/telegram/ext/_updater.py\", line 753, in _network_loop_retry\n",
      "    if not await do_action():\n",
      "           ^^^^^^^^^^^^^^^^^\n",
      "  File \"/Users/iliastulov/miniconda3/lib/python3.12/site-packages/telegram/ext/_updater.py\", line 747, in do_action\n",
      "    return action_cb_task.result()\n",
      "           ^^^^^^^^^^^^^^^^^^^^^^^\n",
      "  File \"/Users/iliastulov/miniconda3/lib/python3.12/asyncio/futures.py\", line 203, in result\n",
      "    raise self._exception.with_traceback(self._exception_tb)\n",
      "  File \"/Users/iliastulov/miniconda3/lib/python3.12/asyncio/tasks.py\", line 314, in __step_run_and_handle_result\n",
      "    result = coro.send(None)\n",
      "             ^^^^^^^^^^^^^^^\n",
      "  File \"/Users/iliastulov/miniconda3/lib/python3.12/site-packages/telegram/ext/_updater.py\", line 377, in polling_action_cb\n",
      "    updates = await self.bot.get_updates(\n",
      "              ^^^^^^^^^^^^^^^^^^^^^^^^^^^\n",
      "  File \"/Users/iliastulov/miniconda3/lib/python3.12/site-packages/telegram/ext/_extbot.py\", line 649, in get_updates\n",
      "    updates = await super().get_updates(\n",
      "              ^^^^^^^^^^^^^^^^^^^^^^^^^^\n",
      "  File \"/Users/iliastulov/miniconda3/lib/python3.12/site-packages/telegram/_bot.py\", line 4366, in get_updates\n",
      "    await self._post(\n",
      "  File \"/Users/iliastulov/miniconda3/lib/python3.12/site-packages/telegram/_bot.py\", line 623, in _post\n",
      "    return await self._do_post(\n",
      "           ^^^^^^^^^^^^^^^^^^^^\n",
      "  File \"/Users/iliastulov/miniconda3/lib/python3.12/site-packages/telegram/ext/_extbot.py\", line 355, in _do_post\n",
      "    return await super()._do_post(\n",
      "           ^^^^^^^^^^^^^^^^^^^^^^^\n",
      "  File \"/Users/iliastulov/miniconda3/lib/python3.12/site-packages/telegram/_bot.py\", line 652, in _do_post\n",
      "    result = await request.post(\n",
      "             ^^^^^^^^^^^^^^^^^^^\n",
      "  File \"/Users/iliastulov/miniconda3/lib/python3.12/site-packages/telegram/request/_baserequest.py\", line 201, in post\n",
      "    result = await self._request_wrapper(\n",
      "             ^^^^^^^^^^^^^^^^^^^^^^^^^^^^\n",
      "  File \"/Users/iliastulov/miniconda3/lib/python3.12/site-packages/telegram/request/_baserequest.py\", line 384, in _request_wrapper\n",
      "    raise Conflict(message)\n",
      "telegram.error.Conflict: Conflict: terminated by other getUpdates request; make sure that only one bot instance is running\n",
      "No error handlers are registered, logging exception.\n",
      "Traceback (most recent call last):\n",
      "  File \"/Users/iliastulov/miniconda3/lib/python3.12/site-packages/telegram/ext/_updater.py\", line 753, in _network_loop_retry\n",
      "    if not await do_action():\n",
      "           ^^^^^^^^^^^^^^^^^\n",
      "  File \"/Users/iliastulov/miniconda3/lib/python3.12/site-packages/telegram/ext/_updater.py\", line 747, in do_action\n",
      "    return action_cb_task.result()\n",
      "           ^^^^^^^^^^^^^^^^^^^^^^^\n",
      "  File \"/Users/iliastulov/miniconda3/lib/python3.12/asyncio/futures.py\", line 203, in result\n",
      "    raise self._exception.with_traceback(self._exception_tb)\n",
      "  File \"/Users/iliastulov/miniconda3/lib/python3.12/asyncio/tasks.py\", line 314, in __step_run_and_handle_result\n",
      "    result = coro.send(None)\n",
      "             ^^^^^^^^^^^^^^^\n",
      "  File \"/Users/iliastulov/miniconda3/lib/python3.12/site-packages/telegram/ext/_updater.py\", line 377, in polling_action_cb\n",
      "    updates = await self.bot.get_updates(\n",
      "              ^^^^^^^^^^^^^^^^^^^^^^^^^^^\n",
      "  File \"/Users/iliastulov/miniconda3/lib/python3.12/site-packages/telegram/ext/_extbot.py\", line 649, in get_updates\n",
      "    updates = await super().get_updates(\n",
      "              ^^^^^^^^^^^^^^^^^^^^^^^^^^\n",
      "  File \"/Users/iliastulov/miniconda3/lib/python3.12/site-packages/telegram/_bot.py\", line 4366, in get_updates\n",
      "    await self._post(\n",
      "  File \"/Users/iliastulov/miniconda3/lib/python3.12/site-packages/telegram/_bot.py\", line 623, in _post\n",
      "    return await self._do_post(\n",
      "           ^^^^^^^^^^^^^^^^^^^^\n",
      "  File \"/Users/iliastulov/miniconda3/lib/python3.12/site-packages/telegram/ext/_extbot.py\", line 355, in _do_post\n",
      "    return await super()._do_post(\n",
      "           ^^^^^^^^^^^^^^^^^^^^^^^\n",
      "  File \"/Users/iliastulov/miniconda3/lib/python3.12/site-packages/telegram/_bot.py\", line 652, in _do_post\n",
      "    result = await request.post(\n",
      "             ^^^^^^^^^^^^^^^^^^^\n",
      "  File \"/Users/iliastulov/miniconda3/lib/python3.12/site-packages/telegram/request/_baserequest.py\", line 201, in post\n",
      "    result = await self._request_wrapper(\n",
      "             ^^^^^^^^^^^^^^^^^^^^^^^^^^^^\n",
      "  File \"/Users/iliastulov/miniconda3/lib/python3.12/site-packages/telegram/request/_baserequest.py\", line 384, in _request_wrapper\n",
      "    raise Conflict(message)\n",
      "telegram.error.Conflict: Conflict: terminated by other getUpdates request; make sure that only one bot instance is running\n",
      "No error handlers are registered, logging exception.\n",
      "Traceback (most recent call last):\n",
      "  File \"/Users/iliastulov/miniconda3/lib/python3.12/site-packages/telegram/ext/_updater.py\", line 753, in _network_loop_retry\n",
      "    if not await do_action():\n",
      "           ^^^^^^^^^^^^^^^^^\n",
      "  File \"/Users/iliastulov/miniconda3/lib/python3.12/site-packages/telegram/ext/_updater.py\", line 747, in do_action\n",
      "    return action_cb_task.result()\n",
      "           ^^^^^^^^^^^^^^^^^^^^^^^\n",
      "  File \"/Users/iliastulov/miniconda3/lib/python3.12/asyncio/futures.py\", line 203, in result\n",
      "    raise self._exception.with_traceback(self._exception_tb)\n",
      "  File \"/Users/iliastulov/miniconda3/lib/python3.12/asyncio/tasks.py\", line 314, in __step_run_and_handle_result\n",
      "    result = coro.send(None)\n",
      "             ^^^^^^^^^^^^^^^\n",
      "  File \"/Users/iliastulov/miniconda3/lib/python3.12/site-packages/telegram/ext/_updater.py\", line 377, in polling_action_cb\n",
      "    updates = await self.bot.get_updates(\n",
      "              ^^^^^^^^^^^^^^^^^^^^^^^^^^^\n",
      "  File \"/Users/iliastulov/miniconda3/lib/python3.12/site-packages/telegram/ext/_extbot.py\", line 649, in get_updates\n",
      "    updates = await super().get_updates(\n",
      "              ^^^^^^^^^^^^^^^^^^^^^^^^^^\n",
      "  File \"/Users/iliastulov/miniconda3/lib/python3.12/site-packages/telegram/_bot.py\", line 4366, in get_updates\n",
      "    await self._post(\n",
      "  File \"/Users/iliastulov/miniconda3/lib/python3.12/site-packages/telegram/_bot.py\", line 623, in _post\n",
      "    return await self._do_post(\n",
      "           ^^^^^^^^^^^^^^^^^^^^\n",
      "  File \"/Users/iliastulov/miniconda3/lib/python3.12/site-packages/telegram/ext/_extbot.py\", line 355, in _do_post\n",
      "    return await super()._do_post(\n",
      "           ^^^^^^^^^^^^^^^^^^^^^^^\n",
      "  File \"/Users/iliastulov/miniconda3/lib/python3.12/site-packages/telegram/_bot.py\", line 652, in _do_post\n",
      "    result = await request.post(\n",
      "             ^^^^^^^^^^^^^^^^^^^\n",
      "  File \"/Users/iliastulov/miniconda3/lib/python3.12/site-packages/telegram/request/_baserequest.py\", line 201, in post\n",
      "    result = await self._request_wrapper(\n",
      "             ^^^^^^^^^^^^^^^^^^^^^^^^^^^^\n",
      "  File \"/Users/iliastulov/miniconda3/lib/python3.12/site-packages/telegram/request/_baserequest.py\", line 384, in _request_wrapper\n",
      "    raise Conflict(message)\n",
      "telegram.error.Conflict: Conflict: terminated by other getUpdates request; make sure that only one bot instance is running\n",
      "No error handlers are registered, logging exception.\n",
      "Traceback (most recent call last):\n",
      "  File \"/Users/iliastulov/miniconda3/lib/python3.12/site-packages/telegram/ext/_updater.py\", line 753, in _network_loop_retry\n",
      "    if not await do_action():\n",
      "           ^^^^^^^^^^^^^^^^^\n",
      "  File \"/Users/iliastulov/miniconda3/lib/python3.12/site-packages/telegram/ext/_updater.py\", line 747, in do_action\n",
      "    return action_cb_task.result()\n",
      "           ^^^^^^^^^^^^^^^^^^^^^^^\n",
      "  File \"/Users/iliastulov/miniconda3/lib/python3.12/asyncio/futures.py\", line 203, in result\n",
      "    raise self._exception.with_traceback(self._exception_tb)\n",
      "  File \"/Users/iliastulov/miniconda3/lib/python3.12/asyncio/tasks.py\", line 314, in __step_run_and_handle_result\n",
      "    result = coro.send(None)\n",
      "             ^^^^^^^^^^^^^^^\n",
      "  File \"/Users/iliastulov/miniconda3/lib/python3.12/site-packages/telegram/ext/_updater.py\", line 377, in polling_action_cb\n",
      "    updates = await self.bot.get_updates(\n",
      "              ^^^^^^^^^^^^^^^^^^^^^^^^^^^\n",
      "  File \"/Users/iliastulov/miniconda3/lib/python3.12/site-packages/telegram/ext/_extbot.py\", line 649, in get_updates\n",
      "    updates = await super().get_updates(\n",
      "              ^^^^^^^^^^^^^^^^^^^^^^^^^^\n",
      "  File \"/Users/iliastulov/miniconda3/lib/python3.12/site-packages/telegram/_bot.py\", line 4366, in get_updates\n",
      "    await self._post(\n",
      "  File \"/Users/iliastulov/miniconda3/lib/python3.12/site-packages/telegram/_bot.py\", line 623, in _post\n",
      "    return await self._do_post(\n",
      "           ^^^^^^^^^^^^^^^^^^^^\n",
      "  File \"/Users/iliastulov/miniconda3/lib/python3.12/site-packages/telegram/ext/_extbot.py\", line 355, in _do_post\n",
      "    return await super()._do_post(\n",
      "           ^^^^^^^^^^^^^^^^^^^^^^^\n",
      "  File \"/Users/iliastulov/miniconda3/lib/python3.12/site-packages/telegram/_bot.py\", line 652, in _do_post\n",
      "    result = await request.post(\n",
      "             ^^^^^^^^^^^^^^^^^^^\n",
      "  File \"/Users/iliastulov/miniconda3/lib/python3.12/site-packages/telegram/request/_baserequest.py\", line 201, in post\n",
      "    result = await self._request_wrapper(\n",
      "             ^^^^^^^^^^^^^^^^^^^^^^^^^^^^\n",
      "  File \"/Users/iliastulov/miniconda3/lib/python3.12/site-packages/telegram/request/_baserequest.py\", line 384, in _request_wrapper\n",
      "    raise Conflict(message)\n",
      "telegram.error.Conflict: Conflict: terminated by other getUpdates request; make sure that only one bot instance is running\n",
      "No error handlers are registered, logging exception.\n",
      "Traceback (most recent call last):\n",
      "  File \"/Users/iliastulov/miniconda3/lib/python3.12/site-packages/telegram/ext/_updater.py\", line 753, in _network_loop_retry\n",
      "    if not await do_action():\n",
      "           ^^^^^^^^^^^^^^^^^\n",
      "  File \"/Users/iliastulov/miniconda3/lib/python3.12/site-packages/telegram/ext/_updater.py\", line 747, in do_action\n",
      "    return action_cb_task.result()\n",
      "           ^^^^^^^^^^^^^^^^^^^^^^^\n",
      "  File \"/Users/iliastulov/miniconda3/lib/python3.12/asyncio/futures.py\", line 203, in result\n",
      "    raise self._exception.with_traceback(self._exception_tb)\n",
      "  File \"/Users/iliastulov/miniconda3/lib/python3.12/asyncio/tasks.py\", line 314, in __step_run_and_handle_result\n",
      "    result = coro.send(None)\n",
      "             ^^^^^^^^^^^^^^^\n",
      "  File \"/Users/iliastulov/miniconda3/lib/python3.12/site-packages/telegram/ext/_updater.py\", line 377, in polling_action_cb\n",
      "    updates = await self.bot.get_updates(\n",
      "              ^^^^^^^^^^^^^^^^^^^^^^^^^^^\n",
      "  File \"/Users/iliastulov/miniconda3/lib/python3.12/site-packages/telegram/ext/_extbot.py\", line 649, in get_updates\n",
      "    updates = await super().get_updates(\n",
      "              ^^^^^^^^^^^^^^^^^^^^^^^^^^\n",
      "  File \"/Users/iliastulov/miniconda3/lib/python3.12/site-packages/telegram/_bot.py\", line 4366, in get_updates\n",
      "    await self._post(\n",
      "  File \"/Users/iliastulov/miniconda3/lib/python3.12/site-packages/telegram/_bot.py\", line 623, in _post\n",
      "    return await self._do_post(\n",
      "           ^^^^^^^^^^^^^^^^^^^^\n",
      "  File \"/Users/iliastulov/miniconda3/lib/python3.12/site-packages/telegram/ext/_extbot.py\", line 355, in _do_post\n",
      "    return await super()._do_post(\n",
      "           ^^^^^^^^^^^^^^^^^^^^^^^\n",
      "  File \"/Users/iliastulov/miniconda3/lib/python3.12/site-packages/telegram/_bot.py\", line 652, in _do_post\n",
      "    result = await request.post(\n",
      "             ^^^^^^^^^^^^^^^^^^^\n",
      "  File \"/Users/iliastulov/miniconda3/lib/python3.12/site-packages/telegram/request/_baserequest.py\", line 201, in post\n",
      "    result = await self._request_wrapper(\n",
      "             ^^^^^^^^^^^^^^^^^^^^^^^^^^^^\n",
      "  File \"/Users/iliastulov/miniconda3/lib/python3.12/site-packages/telegram/request/_baserequest.py\", line 384, in _request_wrapper\n",
      "    raise Conflict(message)\n",
      "telegram.error.Conflict: Conflict: terminated by other getUpdates request; make sure that only one bot instance is running\n",
      "No error handlers are registered, logging exception.\n",
      "Traceback (most recent call last):\n",
      "  File \"/Users/iliastulov/miniconda3/lib/python3.12/site-packages/telegram/ext/_updater.py\", line 753, in _network_loop_retry\n",
      "    if not await do_action():\n",
      "           ^^^^^^^^^^^^^^^^^\n",
      "  File \"/Users/iliastulov/miniconda3/lib/python3.12/site-packages/telegram/ext/_updater.py\", line 747, in do_action\n",
      "    return action_cb_task.result()\n",
      "           ^^^^^^^^^^^^^^^^^^^^^^^\n",
      "  File \"/Users/iliastulov/miniconda3/lib/python3.12/asyncio/futures.py\", line 203, in result\n",
      "    raise self._exception.with_traceback(self._exception_tb)\n",
      "  File \"/Users/iliastulov/miniconda3/lib/python3.12/asyncio/tasks.py\", line 314, in __step_run_and_handle_result\n",
      "    result = coro.send(None)\n",
      "             ^^^^^^^^^^^^^^^\n",
      "  File \"/Users/iliastulov/miniconda3/lib/python3.12/site-packages/telegram/ext/_updater.py\", line 377, in polling_action_cb\n",
      "    updates = await self.bot.get_updates(\n",
      "              ^^^^^^^^^^^^^^^^^^^^^^^^^^^\n",
      "  File \"/Users/iliastulov/miniconda3/lib/python3.12/site-packages/telegram/ext/_extbot.py\", line 649, in get_updates\n",
      "    updates = await super().get_updates(\n",
      "              ^^^^^^^^^^^^^^^^^^^^^^^^^^\n",
      "  File \"/Users/iliastulov/miniconda3/lib/python3.12/site-packages/telegram/_bot.py\", line 4366, in get_updates\n",
      "    await self._post(\n",
      "  File \"/Users/iliastulov/miniconda3/lib/python3.12/site-packages/telegram/_bot.py\", line 623, in _post\n",
      "    return await self._do_post(\n",
      "           ^^^^^^^^^^^^^^^^^^^^\n",
      "  File \"/Users/iliastulov/miniconda3/lib/python3.12/site-packages/telegram/ext/_extbot.py\", line 355, in _do_post\n",
      "    return await super()._do_post(\n",
      "           ^^^^^^^^^^^^^^^^^^^^^^^\n",
      "  File \"/Users/iliastulov/miniconda3/lib/python3.12/site-packages/telegram/_bot.py\", line 652, in _do_post\n",
      "    result = await request.post(\n",
      "             ^^^^^^^^^^^^^^^^^^^\n",
      "  File \"/Users/iliastulov/miniconda3/lib/python3.12/site-packages/telegram/request/_baserequest.py\", line 201, in post\n",
      "    result = await self._request_wrapper(\n",
      "             ^^^^^^^^^^^^^^^^^^^^^^^^^^^^\n",
      "  File \"/Users/iliastulov/miniconda3/lib/python3.12/site-packages/telegram/request/_baserequest.py\", line 384, in _request_wrapper\n",
      "    raise Conflict(message)\n",
      "telegram.error.Conflict: Conflict: terminated by other getUpdates request; make sure that only one bot instance is running\n",
      "No error handlers are registered, logging exception.\n",
      "Traceback (most recent call last):\n",
      "  File \"/Users/iliastulov/miniconda3/lib/python3.12/site-packages/telegram/ext/_updater.py\", line 753, in _network_loop_retry\n",
      "    if not await do_action():\n",
      "           ^^^^^^^^^^^^^^^^^\n",
      "  File \"/Users/iliastulov/miniconda3/lib/python3.12/site-packages/telegram/ext/_updater.py\", line 747, in do_action\n",
      "    return action_cb_task.result()\n",
      "           ^^^^^^^^^^^^^^^^^^^^^^^\n",
      "  File \"/Users/iliastulov/miniconda3/lib/python3.12/asyncio/futures.py\", line 203, in result\n",
      "    raise self._exception.with_traceback(self._exception_tb)\n",
      "  File \"/Users/iliastulov/miniconda3/lib/python3.12/asyncio/tasks.py\", line 314, in __step_run_and_handle_result\n",
      "    result = coro.send(None)\n",
      "             ^^^^^^^^^^^^^^^\n",
      "  File \"/Users/iliastulov/miniconda3/lib/python3.12/site-packages/telegram/ext/_updater.py\", line 377, in polling_action_cb\n",
      "    updates = await self.bot.get_updates(\n",
      "              ^^^^^^^^^^^^^^^^^^^^^^^^^^^\n",
      "  File \"/Users/iliastulov/miniconda3/lib/python3.12/site-packages/telegram/ext/_extbot.py\", line 649, in get_updates\n",
      "    updates = await super().get_updates(\n",
      "              ^^^^^^^^^^^^^^^^^^^^^^^^^^\n",
      "  File \"/Users/iliastulov/miniconda3/lib/python3.12/site-packages/telegram/_bot.py\", line 4366, in get_updates\n",
      "    await self._post(\n",
      "  File \"/Users/iliastulov/miniconda3/lib/python3.12/site-packages/telegram/_bot.py\", line 623, in _post\n",
      "    return await self._do_post(\n",
      "           ^^^^^^^^^^^^^^^^^^^^\n",
      "  File \"/Users/iliastulov/miniconda3/lib/python3.12/site-packages/telegram/ext/_extbot.py\", line 355, in _do_post\n",
      "    return await super()._do_post(\n",
      "           ^^^^^^^^^^^^^^^^^^^^^^^\n",
      "  File \"/Users/iliastulov/miniconda3/lib/python3.12/site-packages/telegram/_bot.py\", line 652, in _do_post\n",
      "    result = await request.post(\n",
      "             ^^^^^^^^^^^^^^^^^^^\n",
      "  File \"/Users/iliastulov/miniconda3/lib/python3.12/site-packages/telegram/request/_baserequest.py\", line 201, in post\n",
      "    result = await self._request_wrapper(\n",
      "             ^^^^^^^^^^^^^^^^^^^^^^^^^^^^\n",
      "  File \"/Users/iliastulov/miniconda3/lib/python3.12/site-packages/telegram/request/_baserequest.py\", line 384, in _request_wrapper\n",
      "    raise Conflict(message)\n",
      "telegram.error.Conflict: Conflict: terminated by other getUpdates request; make sure that only one bot instance is running\n",
      "No error handlers are registered, logging exception.\n",
      "Traceback (most recent call last):\n",
      "  File \"/Users/iliastulov/miniconda3/lib/python3.12/site-packages/telegram/ext/_updater.py\", line 753, in _network_loop_retry\n",
      "    if not await do_action():\n",
      "           ^^^^^^^^^^^^^^^^^\n",
      "  File \"/Users/iliastulov/miniconda3/lib/python3.12/site-packages/telegram/ext/_updater.py\", line 747, in do_action\n",
      "    return action_cb_task.result()\n",
      "           ^^^^^^^^^^^^^^^^^^^^^^^\n",
      "  File \"/Users/iliastulov/miniconda3/lib/python3.12/asyncio/futures.py\", line 203, in result\n",
      "    raise self._exception.with_traceback(self._exception_tb)\n",
      "  File \"/Users/iliastulov/miniconda3/lib/python3.12/asyncio/tasks.py\", line 314, in __step_run_and_handle_result\n",
      "    result = coro.send(None)\n",
      "             ^^^^^^^^^^^^^^^\n",
      "  File \"/Users/iliastulov/miniconda3/lib/python3.12/site-packages/telegram/ext/_updater.py\", line 377, in polling_action_cb\n",
      "    updates = await self.bot.get_updates(\n",
      "              ^^^^^^^^^^^^^^^^^^^^^^^^^^^\n",
      "  File \"/Users/iliastulov/miniconda3/lib/python3.12/site-packages/telegram/ext/_extbot.py\", line 649, in get_updates\n",
      "    updates = await super().get_updates(\n",
      "              ^^^^^^^^^^^^^^^^^^^^^^^^^^\n",
      "  File \"/Users/iliastulov/miniconda3/lib/python3.12/site-packages/telegram/_bot.py\", line 4366, in get_updates\n",
      "    await self._post(\n",
      "  File \"/Users/iliastulov/miniconda3/lib/python3.12/site-packages/telegram/_bot.py\", line 623, in _post\n",
      "    return await self._do_post(\n",
      "           ^^^^^^^^^^^^^^^^^^^^\n",
      "  File \"/Users/iliastulov/miniconda3/lib/python3.12/site-packages/telegram/ext/_extbot.py\", line 355, in _do_post\n",
      "    return await super()._do_post(\n",
      "           ^^^^^^^^^^^^^^^^^^^^^^^\n",
      "  File \"/Users/iliastulov/miniconda3/lib/python3.12/site-packages/telegram/_bot.py\", line 652, in _do_post\n",
      "    result = await request.post(\n",
      "             ^^^^^^^^^^^^^^^^^^^\n",
      "  File \"/Users/iliastulov/miniconda3/lib/python3.12/site-packages/telegram/request/_baserequest.py\", line 201, in post\n",
      "    result = await self._request_wrapper(\n",
      "             ^^^^^^^^^^^^^^^^^^^^^^^^^^^^\n",
      "  File \"/Users/iliastulov/miniconda3/lib/python3.12/site-packages/telegram/request/_baserequest.py\", line 384, in _request_wrapper\n",
      "    raise Conflict(message)\n",
      "telegram.error.Conflict: Conflict: terminated by other getUpdates request; make sure that only one bot instance is running\n"
     ]
    },
    {
     "ename": "RuntimeError",
     "evalue": "Cannot close a running event loop",
     "output_type": "error",
     "traceback": [
      "\u001b[0;31m---------------------------------------------------------------------------\u001b[0m",
      "\u001b[0;31mRuntimeError\u001b[0m                              Traceback (most recent call last)",
      "Cell \u001b[0;32mIn[7], line 170\u001b[0m\n\u001b[1;32m    167\u001b[0m application\u001b[38;5;241m.\u001b[39madd_handler(CallbackQueryHandler(button_handler))\n\u001b[1;32m    168\u001b[0m application\u001b[38;5;241m.\u001b[39madd_handler(MessageHandler(filters\u001b[38;5;241m.\u001b[39mTEXT, message_handler))\n\u001b[0;32m--> 170\u001b[0m \u001b[43mapplication\u001b[49m\u001b[38;5;241;43m.\u001b[39;49m\u001b[43mrun_polling\u001b[49m\u001b[43m(\u001b[49m\u001b[43m)\u001b[49m\n",
      "File \u001b[0;32m~/miniconda3/lib/python3.12/site-packages/telegram/ext/_application.py:881\u001b[0m, in \u001b[0;36mApplication.run_polling\u001b[0;34m(self, poll_interval, timeout, bootstrap_retries, read_timeout, write_timeout, connect_timeout, pool_timeout, allowed_updates, drop_pending_updates, close_loop, stop_signals)\u001b[0m\n\u001b[1;32m    878\u001b[0m \u001b[38;5;28;01mdef\u001b[39;00m \u001b[38;5;21merror_callback\u001b[39m(exc: TelegramError) \u001b[38;5;241m-\u001b[39m\u001b[38;5;241m>\u001b[39m \u001b[38;5;28;01mNone\u001b[39;00m:\n\u001b[1;32m    879\u001b[0m     \u001b[38;5;28mself\u001b[39m\u001b[38;5;241m.\u001b[39mcreate_task(\u001b[38;5;28mself\u001b[39m\u001b[38;5;241m.\u001b[39mprocess_error(error\u001b[38;5;241m=\u001b[39mexc, update\u001b[38;5;241m=\u001b[39m\u001b[38;5;28;01mNone\u001b[39;00m))\n\u001b[0;32m--> 881\u001b[0m \u001b[38;5;28;01mreturn\u001b[39;00m \u001b[38;5;28;43mself\u001b[39;49m\u001b[38;5;241;43m.\u001b[39;49m\u001b[43m__run\u001b[49m\u001b[43m(\u001b[49m\n\u001b[1;32m    882\u001b[0m \u001b[43m    \u001b[49m\u001b[43mupdater_coroutine\u001b[49m\u001b[38;5;241;43m=\u001b[39;49m\u001b[38;5;28;43mself\u001b[39;49m\u001b[38;5;241;43m.\u001b[39;49m\u001b[43mupdater\u001b[49m\u001b[38;5;241;43m.\u001b[39;49m\u001b[43mstart_polling\u001b[49m\u001b[43m(\u001b[49m\n\u001b[1;32m    883\u001b[0m \u001b[43m        \u001b[49m\u001b[43mpoll_interval\u001b[49m\u001b[38;5;241;43m=\u001b[39;49m\u001b[43mpoll_interval\u001b[49m\u001b[43m,\u001b[49m\n\u001b[1;32m    884\u001b[0m \u001b[43m        \u001b[49m\u001b[43mtimeout\u001b[49m\u001b[38;5;241;43m=\u001b[39;49m\u001b[43mtimeout\u001b[49m\u001b[43m,\u001b[49m\n\u001b[1;32m    885\u001b[0m \u001b[43m        \u001b[49m\u001b[43mbootstrap_retries\u001b[49m\u001b[38;5;241;43m=\u001b[39;49m\u001b[43mbootstrap_retries\u001b[49m\u001b[43m,\u001b[49m\n\u001b[1;32m    886\u001b[0m \u001b[43m        \u001b[49m\u001b[43mread_timeout\u001b[49m\u001b[38;5;241;43m=\u001b[39;49m\u001b[43mread_timeout\u001b[49m\u001b[43m,\u001b[49m\n\u001b[1;32m    887\u001b[0m \u001b[43m        \u001b[49m\u001b[43mwrite_timeout\u001b[49m\u001b[38;5;241;43m=\u001b[39;49m\u001b[43mwrite_timeout\u001b[49m\u001b[43m,\u001b[49m\n\u001b[1;32m    888\u001b[0m \u001b[43m        \u001b[49m\u001b[43mconnect_timeout\u001b[49m\u001b[38;5;241;43m=\u001b[39;49m\u001b[43mconnect_timeout\u001b[49m\u001b[43m,\u001b[49m\n\u001b[1;32m    889\u001b[0m \u001b[43m        \u001b[49m\u001b[43mpool_timeout\u001b[49m\u001b[38;5;241;43m=\u001b[39;49m\u001b[43mpool_timeout\u001b[49m\u001b[43m,\u001b[49m\n\u001b[1;32m    890\u001b[0m \u001b[43m        \u001b[49m\u001b[43mallowed_updates\u001b[49m\u001b[38;5;241;43m=\u001b[39;49m\u001b[43mallowed_updates\u001b[49m\u001b[43m,\u001b[49m\n\u001b[1;32m    891\u001b[0m \u001b[43m        \u001b[49m\u001b[43mdrop_pending_updates\u001b[49m\u001b[38;5;241;43m=\u001b[39;49m\u001b[43mdrop_pending_updates\u001b[49m\u001b[43m,\u001b[49m\n\u001b[1;32m    892\u001b[0m \u001b[43m        \u001b[49m\u001b[43merror_callback\u001b[49m\u001b[38;5;241;43m=\u001b[39;49m\u001b[43merror_callback\u001b[49m\u001b[43m,\u001b[49m\u001b[43m  \u001b[49m\u001b[38;5;66;43;03m# if there is an error in fetching updates\u001b[39;49;00m\n\u001b[1;32m    893\u001b[0m \u001b[43m    \u001b[49m\u001b[43m)\u001b[49m\u001b[43m,\u001b[49m\n\u001b[1;32m    894\u001b[0m \u001b[43m    \u001b[49m\u001b[43mclose_loop\u001b[49m\u001b[38;5;241;43m=\u001b[39;49m\u001b[43mclose_loop\u001b[49m\u001b[43m,\u001b[49m\n\u001b[1;32m    895\u001b[0m \u001b[43m    \u001b[49m\u001b[43mstop_signals\u001b[49m\u001b[38;5;241;43m=\u001b[39;49m\u001b[43mstop_signals\u001b[49m\u001b[43m,\u001b[49m\n\u001b[1;32m    896\u001b[0m \u001b[43m\u001b[49m\u001b[43m)\u001b[49m\n",
      "File \u001b[0;32m~/miniconda3/lib/python3.12/site-packages/telegram/ext/_application.py:1109\u001b[0m, in \u001b[0;36mApplication.__run\u001b[0;34m(self, updater_coroutine, stop_signals, close_loop)\u001b[0m\n\u001b[1;32m   1107\u001b[0m \u001b[38;5;28;01mfinally\u001b[39;00m:\n\u001b[1;32m   1108\u001b[0m     \u001b[38;5;28;01mif\u001b[39;00m close_loop:\n\u001b[0;32m-> 1109\u001b[0m         \u001b[43mloop\u001b[49m\u001b[38;5;241;43m.\u001b[39;49m\u001b[43mclose\u001b[49m\u001b[43m(\u001b[49m\u001b[43m)\u001b[49m\n",
      "File \u001b[0;32m~/miniconda3/lib/python3.12/asyncio/unix_events.py:68\u001b[0m, in \u001b[0;36m_UnixSelectorEventLoop.close\u001b[0;34m(self)\u001b[0m\n\u001b[1;32m     67\u001b[0m \u001b[38;5;28;01mdef\u001b[39;00m \u001b[38;5;21mclose\u001b[39m(\u001b[38;5;28mself\u001b[39m):\n\u001b[0;32m---> 68\u001b[0m     \u001b[38;5;28;43msuper\u001b[39;49m\u001b[43m(\u001b[49m\u001b[43m)\u001b[49m\u001b[38;5;241;43m.\u001b[39;49m\u001b[43mclose\u001b[49m\u001b[43m(\u001b[49m\u001b[43m)\u001b[49m\n\u001b[1;32m     69\u001b[0m     \u001b[38;5;28;01mif\u001b[39;00m \u001b[38;5;129;01mnot\u001b[39;00m sys\u001b[38;5;241m.\u001b[39mis_finalizing():\n\u001b[1;32m     70\u001b[0m         \u001b[38;5;28;01mfor\u001b[39;00m sig \u001b[38;5;129;01min\u001b[39;00m \u001b[38;5;28mlist\u001b[39m(\u001b[38;5;28mself\u001b[39m\u001b[38;5;241m.\u001b[39m_signal_handlers):\n",
      "File \u001b[0;32m~/miniconda3/lib/python3.12/asyncio/selector_events.py:101\u001b[0m, in \u001b[0;36mBaseSelectorEventLoop.close\u001b[0;34m(self)\u001b[0m\n\u001b[1;32m     99\u001b[0m \u001b[38;5;28;01mdef\u001b[39;00m \u001b[38;5;21mclose\u001b[39m(\u001b[38;5;28mself\u001b[39m):\n\u001b[1;32m    100\u001b[0m     \u001b[38;5;28;01mif\u001b[39;00m \u001b[38;5;28mself\u001b[39m\u001b[38;5;241m.\u001b[39mis_running():\n\u001b[0;32m--> 101\u001b[0m         \u001b[38;5;28;01mraise\u001b[39;00m \u001b[38;5;167;01mRuntimeError\u001b[39;00m(\u001b[38;5;124m\"\u001b[39m\u001b[38;5;124mCannot close a running event loop\u001b[39m\u001b[38;5;124m\"\u001b[39m)\n\u001b[1;32m    102\u001b[0m     \u001b[38;5;28;01mif\u001b[39;00m \u001b[38;5;28mself\u001b[39m\u001b[38;5;241m.\u001b[39mis_closed():\n\u001b[1;32m    103\u001b[0m         \u001b[38;5;28;01mreturn\u001b[39;00m\n",
      "\u001b[0;31mRuntimeError\u001b[0m: Cannot close a running event loop"
     ]
    }
   ],
   "source": [
    "import instaloader\n",
    "import time\n",
    "from telegram import Update, InlineKeyboardButton, InlineKeyboardMarkup\n",
    "from telegram.ext import ApplicationBuilder, CommandHandler, CallbackQueryHandler, MessageHandler, filters\n",
    "import pandas as pd\n",
    "import re\n",
    "import nest_asyncio\n",
    "\n",
    "# Применяем патч для работы с текущим event loop\n",
    "nest_asyncio.apply()\n",
    "\n",
    "# Инициализация Instaloader для анализа профиля\n",
    "L = instaloader.Instaloader()\n",
    "\n",
    "# Заменить на свои учетные данные Instagram\n",
    "L.login(\"USER_NAME\", \"PASSWORD\")\n",
    "\n",
    "# Функция для создания таблиц с анализом\n",
    "async def analyze_instagram_profile(username, update):\n",
    "    try:\n",
    "        await update.message.reply_text('Ищу профиль в Instagram...')\n",
    "        profile = instaloader.Profile.from_username(L.context, username)\n",
    "\n",
    "        # Получаем основную информацию о профиле\n",
    "        await update.message.reply_text('Собираю основную информацию о профиле...')\n",
    "        general_info = {\n",
    "            \"Profile URL\": [f\"https://instagram.com/{username}\"],\n",
    "            \"Posts\": [profile.mediacount],\n",
    "            \"Followers\": [profile.followers],\n",
    "            \"Followings\": [profile.followees],\n",
    "            \"Bio\": [profile.biography]\n",
    "        }\n",
    "\n",
    "        # Преобразуем итератор постов в список\n",
    "        await update.message.reply_text('Собираю посты...')\n",
    "        posts = list(profile.get_posts())\n",
    "\n",
    "        # Поиск поста с наибольшим количеством лайков\n",
    "        await update.message.reply_text('Ищу лучший пост по количеству лайков...')\n",
    "        best_post = max(posts, key=lambda post: post.likes)\n",
    "        general_info[\"Best Post URL\"] = [f\"https://instagram.com/p/{best_post.shortcode}/\"]\n",
    "        general_info[\"Best Post Likes\"] = [best_post.likes]\n",
    "        general_info[\"Best Post Comments\"] = [best_post.comments]\n",
    "\n",
    "        # Рассчитываем частоту публикаций\n",
    "        await update.message.reply_text('Рассчитываю частоту публикаций...')\n",
    "        if len(posts) > 1:\n",
    "            post_frequency = (posts[0].date - posts[-1].date).days / len(posts)\n",
    "        else:\n",
    "            post_frequency = \"N/A\"\n",
    "        \n",
    "        general_info[\"Post Frequency (days between posts)\"] = [post_frequency]\n",
    "\n",
    "        # Рассчитываем уровень вовлеченности\n",
    "        await update.message.reply_text('Рассчитываю вовлечённость...')\n",
    "        general_info[\"Engagement Rate\"] = [best_post.likes / profile.followers * 100] if profile.followers > 0 else 0\n",
    "\n",
    "        # Создаем первую таблицу с общей информацией\n",
    "        await update.message.reply_text('Создаю таблицу с общей информацией...')\n",
    "        df_general = pd.DataFrame(general_info)\n",
    "        general_info_file = f\"{username}_general_info.xlsx\"\n",
    "        df_general.to_excel(general_info_file, index=False)\n",
    "\n",
    "        # Отправляем первую таблицу пользователю\n",
    "        await update.message.reply_text('Отправляю первую таблицу с общей информацией...')\n",
    "        await update.message.reply_document(document=open(general_info_file, 'rb'))\n",
    "\n",
    "        # После этого переходим к сбору информации о постах\n",
    "        await update.message.reply_text('Анализирую посты...')\n",
    "\n",
    "        # Анализируем 10 постов с паузами между запросами\n",
    "        post_data = []\n",
    "        for post in posts[:10]:\n",
    "            try:\n",
    "                # Преобразуем комментарии в список, чтобы избежать ошибок с итератором\n",
    "                comments = list(post.get_comments())\n",
    "                hashtags = \" \".join(post.caption_hashtags)\n",
    "                top_comments = [f\"@{comment.owner.username}: {comment.text}\" for comment in comments[:10]]\n",
    "                external_links = ', '.join([link for link in post.caption_mentions])\n",
    "                \n",
    "                # Форматируем дату и время\n",
    "                post_date = post.date.strftime(\"%Y-%m-%d\")\n",
    "                post_time = post.date.strftime(\"%H:%M:%S\")\n",
    "                \n",
    "                post_data.append({\n",
    "                    \"Post URL\": f\"https://instagram.com/p/{post.shortcode}/\",\n",
    "                    \"Post Date\": post_date,\n",
    "                    \"Post Time\": post_time,\n",
    "                    \"Likes\": post.likes,\n",
    "                    \"Comments\": post.comments,\n",
    "                    \"Hashtags\": hashtags,\n",
    "                    \"Post Text\": post.caption,\n",
    "                    \"Top 10 Comments\": \"; \".join(top_comments),\n",
    "                    \"External Links\": external_links\n",
    "                })\n",
    "                # Добавляем паузу между запросами, чтобы избежать блокировок\n",
    "                time.sleep(2)\n",
    "            except Exception as e:\n",
    "                print(f\"Error during post analysis: {str(e)}\")\n",
    "                continue\n",
    "\n",
    "        # Создаем вторую таблицу с анализом постов\n",
    "        await update.message.reply_text('Создаю таблицу с анализом постов...')\n",
    "        df_posts = pd.DataFrame(post_data)\n",
    "        posts_info_file = f\"{username}_posts_info.xlsx\"\n",
    "        df_posts.to_excel(posts_info_file, index=False)\n",
    "\n",
    "        return general_info_file, posts_info_file\n",
    "    except Exception as e:\n",
    "        await update.message.reply_text(f'Произошла ошибка: {str(e)}')\n",
    "        return None, str(e)\n",
    "\n",
    "# Функция для извлечения username из URL\n",
    "def extract_username_from_url(profile_url):\n",
    "    match = re.match(r\"(?:http[s]?://)?(?:www\\.)?instagram\\.com/([A-Za-z0-9._]+)/?\", profile_url)\n",
    "    if match:\n",
    "        return match.group(1)\n",
    "    return None\n",
    "\n",
    "# Хэндлер для старта\n",
    "async def start(update: Update, context):\n",
    "    keyboard = [\n",
    "        [InlineKeyboardButton(\"Info\", callback_data='info')],\n",
    "        [InlineKeyboardButton(\"Analysis (table)\", callback_data='analysis_table')],\n",
    "        [InlineKeyboardButton(\"Analysis (ChatGPT)\", callback_data='analysis_chatgpt')]\n",
    "    ]\n",
    "    reply_markup = InlineKeyboardMarkup(keyboard)\n",
    "    await update.message.reply_text('Welcome to the Instagram Analysis Bot!', reply_markup=reply_markup)\n",
    "\n",
    "# Хэндлер для обработки кнопок\n",
    "async def button_handler(update: Update, context):\n",
    "    query = update.callback_query\n",
    "    await query.answer()\n",
    "\n",
    "    if query.data == 'info':\n",
    "        await query.message.reply_text('Привет! Этот бот анализирует Instagram профили.')\n",
    "    elif query.data == 'analysis_table':\n",
    "        await query.message.reply_text('Пожалуйста, вставьте ссылку на профиль в Instagram (например: https://instagram.com/user_name).')\n",
    "        context.user_data['action'] = 'analysis_table'\n",
    "\n",
    "# Хэндлер для обработки сообщений\n",
    "async def message_handler(update: Update, context):\n",
    "    if 'action' in context.user_data and context.user_data['action'] == 'analysis_table':\n",
    "        profile_url = update.message.text.strip()\n",
    "\n",
    "        # Извлекаем username из URL\n",
    "        username = extract_username_from_url(profile_url)\n",
    "\n",
    "        if username:\n",
    "            await update.message.reply_text(f'Начинаю анализ профиля {username}...')\n",
    "            general_info_file, posts_info_file = await analyze_instagram_profile(username, update)\n",
    "\n",
    "            if general_info_file:\n",
    "                await update.message.reply_document(document=open(posts_info_file, 'rb'))\n",
    "            else:\n",
    "                await update.message.reply_text(f'Произошла ошибка: {posts_info_file}')\n",
    "        else:\n",
    "            await update.message.reply_text('Неверный формат ссылки. Пожалуйста, вставьте правильную ссылку на профиль Instagram.')\n",
    "\n",
    "        context.user_data['action'] = None\n",
    "\n",
    "# Основная функция\n",
    "if __name__ == '__main__':\n",
    "    application = ApplicationBuilder().token('TOKEN_TELEGA_BOT').build()\n",
    "\n",
    "    application.add_handler(CommandHandler('start', start))\n",
    "    application.add_handler(CallbackQueryHandler(button_handler))\n",
    "    application.add_handler(MessageHandler(filters.TEXT, message_handler))\n",
    "\n",
    "    application.run_polling()\n"
   ]
  },
  {
   "cell_type": "code",
   "execution_count": null,
   "id": "6f890ba2-0711-4f61-8bea-604392d2e14f",
   "metadata": {},
   "outputs": [],
   "source": []
  }
 ],
 "metadata": {
  "kernelspec": {
   "display_name": "Python 3 (ipykernel)",
   "language": "python",
   "name": "python3"
  },
  "language_info": {
   "codemirror_mode": {
    "name": "ipython",
    "version": 3
   },
   "file_extension": ".py",
   "mimetype": "text/x-python",
   "name": "python",
   "nbconvert_exporter": "python",
   "pygments_lexer": "ipython3",
   "version": "3.12.1"
  }
 },
 "nbformat": 4,
 "nbformat_minor": 5
}
